Workbook
Name cnes_cnv_equipebr132935186_212_98_254: aps_equipes_esf!$A$884:$L$942
Name cnes_cnv_equipebr133552186_212_98_254: aps_equipes_esf!$A$943:$L$979
Name cnes_cnv_equipebr141509186_212_98_254: aps_equipes_ap1!$A$223:$L$258
Name cnes_cnv_equipebr142024186_212_98_254: ft_equipes_acs!$A$586:$L$654
Name cnes_cnv_servc2br190248186_212_98_254: ci_pa_clinico!$A$355:$L$400
Name deepseek_csv_20260103_403e55: ci_pa_clinico!$A$1:$C$353
Name deepseek_csv_20260103_47bacb: ci_leitos_internacao!$A$1:$C$727
Name deepseek_csv_20260103_6c6bf3: ci_hospitais_internacao!$A$1:$C$727
Name deepseek_csv_20260104_20d45e: aps_equipes_esf!$A$585:$C$881
Name deepseek_csv_20260104_4f976d: ft_enfermeiros!$A$1:$C$694
Name deepseek_csv_20260104_5c32f5: aps_equipes_ap2!$A$1:$C$100
Name deepseek_csv_20260104_79b2e0: aps_equipes_esf!$A$1:$C$584
Name deepseek_csv_20260104_df6ff8: ft_medicos_clinicos!$A$1:$C$705
Name deepseek_csv_20260104_efcd65: aps_equipes_ap1!$A$1:$C$221
Name deepseek_csv_20260104_f19835: ft_equipes_acs!$A$1:$C$584
Name deepseek_csv_20260105_5d445e: casos!$A$1:$C$716
Name deepseek_csv_20260105_fcc3b6: obitos!$A$1:$C$683
Name sinannet_cnv_denguebbr213106186_212_98_254: casos!$A$721:$M$818
Name sinannet_cnv_denguebbr213744186_212_98_254: obitos!$A$688:$M$783

Sheet base
A1: nome_munic | B1: cod_munic | C1: ano | D1: populacao | E1: ft_medicos_clinicos | F1: ft_enfermeiros | G1: ft_equipes_acs | H1: ci_leitos_internacao | I1: ci_hospitais_internacao | J1: ci_pa_clinico | K1: aps_equipes_esf | L1: notificacoes_dengue | M1: notificacoes_srag | N1: internacoes_diabetes | O1: cirurgias_eletivas | P1: exames_diagnosticos | Q1: internacoes_hipertensao | R1: consultas_pre_natais | S1: consultas_atencao_primaria
A2: Porto Velho (RO) | B2: 110020 | C2: 2015 | D2: {=IFERROR(INDEX(fesp!$D:$D, MATCH(1, (VALUE(LEFT(fesp!$A:$A,6))=VALUE(LEFT(B2,6)))*(fesp!$C:$C=C2), 0)), "")} -> 502748 | E2: {=IFERROR(INDEX(ft_medicos_clinicos!$C:$C, MATCH(1, (VALUE(LEFT(ft_medicos_clinicos!$A:$A,6))=VALUE(LEFT(B2,6)))*(ft_medicos_clinicos!$B:$B=C2), 0)), "")} -> 324 | F2: {=IFERROR(INDEX(ft_enfermeiros!$C:$C, MATCH(1, (VALUE(LEFT(ft_enfermeiros!$A:$A,6))=VALUE(LEFT(B2,6)))*(ft_enfermeiros!$B:$B=C2), 0)), "")} -> 505 | G2: {=IFERROR(INDEX(ft_equipes_acs!$C:$C, MATCH(1, (VALUE(LEFT(ft_equipes_acs!$A:$A,6))=VALUE(LEFT(B2,6)))*(ft_equipes_acs!$B:$B=C2), 0)), "")} -> - | H2: {=IFERROR(INDEX(ci_leitos_internacao!$C:$C, MATCH(1, (VALUE(LEFT(ci_leitos_internacao!$A:$A,6))=VALUE(LEFT(B2,6)))*(ci_leitos_internacao!$B:$B=C2), 0)), "")} -> 1654 | I2: {=IFERROR(INDEX(ci_hospitais_internacao!$C:$C, MATCH(1, (VALUE(LEFT(ci_hospitais_internacao!$A:$A,6))=VALUE(LEFT(B2,6)))*(ci_hospitais_internacao!$B:$B=C2), 0)), "")} -> 7 | J2: {=IFERROR(INDEX(ci_pa_clinico!$C:$C, MATCH(1, (VALUE(LEFT(ci_pa_clinico!$A:$A,6))=VALUE(LEFT(B2,6)))*(ci_pa_clinico!$B:$B=C2), 0)), "")} -> 5 | K2: {=IFERROR(INDEX(aps_equipes_esf!$C:$C, MATCH(1, (VALUE(LEFT(aps_equipes_esf!$A:$A,6))=VALUE(LEFT(B2,6)))*(aps_equipes_esf!$B:$B=C2), 0)), "")} -> 19 | L2: {=IFERROR(INDEX(casos!$C:$C, MATCH(1, (VALUE(LEFT(casos!$A:$A,6))=VALUE(LEFT(B2,6)))*(casos!$B:$B=C2), 0)), "")} -> 233 | M2: {=IFERROR(INDEX(srag!$D:$D, MATCH(1, (VALUE(LEFT(srag!$A:$A,6))=VALUE(LEFT(B2,6)))*(srag!$C:$C=C2), 0)), "")} -> 21 | N2: {=IFERROR(INDEX(fesp!$E:$E, MATCH(1, (VALUE(LEFT(fesp!$A:$A,6))=VALUE(LEFT(B2,6)))*(fesp!$C:$C=C2), 0)), "")} -> 114 | O2: {=IFERROR(INDEX(fesp!$F:$F, MATCH(1, (VALUE(LEFT(fesp!$A:$A,6))=VALUE(LEFT(B2,6)))*(fesp!$C:$C=C2), 0)), "")} -> 652 | P2: {=IFERROR(INDEX(fesp!$G:$G, MATCH(1, (VALUE(LEFT(fesp!$A:$A,6))=VALUE(LEFT(B2,6)))*(fesp!$C:$C=C2), 0)), "")} -> 4574081 | Q2: {=IFERROR(INDEX(fesp!$H:$H, MATCH(1, (VALUE(LEFT(fesp!$A:$A,6))=VALUE(LEFT(B2,6)))*(fesp!$C:$C=C2), 0)), "")} -> 25 | R2: {=IFERROR(INDEX(fesp!$I:$I, MATCH(1, (VALUE(LEFT(fesp!$A:$A,6))=VALUE(LEFT(B2,6)))*(fesp!$C:$C=C2), 0)), "")} -> 35047 | S2: {=IFERROR(INDEX(fesp!$J:$J, MATCH(1, (VALUE(LEFT(fesp!$A:$A,6))=VALUE(LEFT(B2,6)))*(fesp!$C:$C=C2), 0)), "")} -> 171666
A3: Porto Velho (RO) | B3: 110020 | C3: 2016 | D3: {=IFERROR(INDEX(fesp!$D:$D, MATCH(1, (VALUE(LEFT(fesp!$A:$A,6))=VALUE(LEFT(B3,6)))*(fesp!$C:$C=C3), 0)), "")} -> 0 | E3: {=IFERROR(INDEX(ft_medicos_clinicos!$C:$C, MATCH(1, (VALUE(LEFT(ft_medicos_clinicos!$A:$A,6))=VALUE(LEFT(B3,6)))*(ft_medicos_clinicos!$B:$B=C3), 0)), "")} -> 305 | F3: {=IFERROR(INDEX(ft_enfermeiros!$C:$C, MATCH(1, (VALUE(LEFT(ft_enfermeiros!$A:$A,6))=VALUE(LEFT(B3,6)))*(ft_enfermeiros!$B:$B=C3), 0)), "")} -> 604 | G3: {=IFERROR(INDEX(ft_equipes_acs!$C:$C, MATCH(1, (VALUE(LEFT(ft_equipes_acs!$A:$A,6))=VALUE(LEFT(B3,6)))*(ft_equipes_acs!$B:$B=C3), 0)), "")} -> - | H3: {=IFERROR(INDEX(ci_leitos_internacao!$C:$C, MATCH(1, (VALUE(LEFT(ci_leitos_internacao!$A:$A,6))=VALUE(LEFT(B3,6)))*(ci_leitos_internacao!$B:$B=C3), 0)), "")} -> 1666 | I3: {=IFERROR(INDEX(ci_hospitais_internacao!$C:$C, MATCH(1, (VALUE(LEFT(ci_hospitais_internacao!$A:$A,6))=VALUE(LEFT(B3,6)))*(ci_hospitais_internacao!$B:$B=C3), 0)), "")} -> 6 | J3: {=IFERROR(INDEX(ci_pa_clinico!$C:$C, MATCH(1, (VALUE(LEFT(ci_pa_clinico!$A:$A,6))=VALUE(LEFT(B3,6)))*(ci_pa_clinico!$B:$B=C3), 0)), "")} -> 6 | K3: {=IFERROR(INDEX(aps_equipes_esf!$C:$C, MATCH(1, (VALUE(LEFT(aps_equipes_esf!$A:$A,6))=VALUE(LEFT(B3,6)))*(aps_equipes_esf!$B:$B=C3), 0)), "")} -> 18 | L3: {=IFERROR(INDEX(casos!$C:$C, MATCH(1, (VALUE(LEFT(casos!$A:$A,6))=VALUE(LEFT(B3,6)))*(casos!$B:$B=C3), 0)), "")} -> 1009 | M3: {=IFERROR(INDEX(srag!$D:$D, MATCH(1, (VALUE(LEFT(srag!$A:$A,6))=VALUE(LEFT(B3,6)))*(srag!$C:$C=C3), 0)), "")} -> 62 | N3: {=IFERROR(INDEX(fesp!$E:$E, MATCH(1, (VALUE(LEFT(fesp!$A:$A,6))=VALUE(LEFT(B3,6)))*(fesp!$C:$C=C3), 0)), "")} -> 114 | O3: {=IFERROR(INDEX(fesp!$F:$F, MATCH(1, (VALUE(LEFT(fesp!$A:$A,6))=VALUE(LEFT(B3,6)))*(fesp!$C:$C=C3), 0)), "")} -> 2413 | P3: {=IFERROR(INDEX(fesp!$G:$G, MATCH(1, (VALUE(LEFT(fesp!$A:$A,6))=VALUE(LEFT(B3,6)))*(fesp!$C:$C=C3), 0)), "")} -> 4546321 | Q3: {=IFERROR(INDEX(fesp!$H:$H, MATCH(1, (VALUE(LEFT(fesp!$A:$A,6))=VALUE(LEFT(B3,6)))*(fesp!$C:$C=C3), 0)), "")} -> 39 | R3: {=IFERROR(INDEX(fesp!$I:$I, MATCH(1, (VALUE(LEFT(fesp!$A:$A,6))=VALUE(LEFT(B3,6)))*(fesp!$C:$C=C3), 0)), "")} -> 29870 | S3: {=IFERROR(INDEX(fesp!$J:$J, MATCH(1, (VALUE(LEFT(fesp!$A:$A,6))=VALUE(LEFT(B3,6)))*(fesp!$C:$C=C3), 0)), "")} -> 165475
A4: Porto Velho (RO) | B4: 1100205 | C4: 2017 | D4: {=IFERROR(INDEX(fesp!$D:$D, MATCH(1, (VALUE(LEFT(fesp!$A:$A,6))=VALUE(LEFT(B4,6)))*(fesp!$C:$C=C4), 0)), "")} -> 0 | E4: {=IFERROR(INDEX(ft_medicos_clinicos!$C:$C, MATCH(1, (VALUE(LEFT(ft_medicos_clinicos!$A:$A,6))=VALUE(LEFT(B4,6)))*(ft_medicos_clinicos!$B:$B=C4), 0)), "")} -> 322 | F4: {=IFERROR(INDEX(ft_enfermeiros!$C:$C, MATCH(1, (VALUE(LEFT(ft_enfermeiros!$A:$A,6))=VALUE(LEFT(B4,6)))*(ft_enfermeiros!$B:$B=C4), 0)), "")} -> 645 | G4: {=IFERROR(INDEX(ft_equipes_acs!$C:$C, MATCH(1, (VALUE(LEFT(ft_equipes_acs!$A:$A,6))=VALUE(LEFT(B4,6)))*(ft_equipes_acs!$B:$B=C4), 0)), "")} -> 1 | H4: {=IFERROR(INDEX(ci_leitos_internacao!$C:$C, MATCH(1, (VALUE(LEFT(ci_leitos_internacao!$A:$A,6))=VALUE(LEFT(B4,6)))*(ci_leitos_internacao!$B:$B=C4), 0)), "")} -> 1715 | I4: {=IFERROR(INDEX(ci_hospitais_internacao!$C:$C, MATCH(1, (VALUE(LEFT(ci_hospitais_internacao!$A:$A,6))=VALUE(LEFT(B4,6)))*(ci_hospitais_internacao!$B:$B=C4), 0)), "")} -> 6 | J4: {=IFERROR(INDEX(ci_pa_clinico!$C:$C, MATCH(1, (VALUE(LEFT(ci_pa_clinico!$A:$A,6))=VALUE(LEFT(B4,6)))*(ci_pa_clinico!$B:$B=C4), 0)), "")} -> 6 | K4: {=IFERROR(INDEX(aps_equipes_esf!$C:$C, MATCH(1, (VALUE(LEFT(aps_equipes_esf!$A:$A,6))=VALUE(LEFT(B4,6)))*(aps_equipes_esf!$B:$B=C4), 0)), "")} -> 24 | L4: {=IFERROR(INDEX(casos!$C:$C, MATCH(1, (VALUE(LEFT(casos!$A:$A,6))=VALUE(LEFT(B4,6)))*(casos!$B:$B=C4), 0)), "")} -> 357 | M4: {=IFERROR(INDEX(srag!$D:$D, MATCH(1, (VALUE(LEFT(srag!$A:$A,6))=VALUE(LEFT(B4,6)))*(srag!$C:$C=C4), 0)), "")} -> 10 | N4: {=IFERROR(INDEX(fesp!$E:$E, MATCH(1, (VALUE(LEFT(fesp!$A:$A,6))=VALUE(LEFT(B4,6)))*(fesp!$C:$C=C4), 0)), "")} -> 85 | O4: {=IFERROR(INDEX(fesp!$F:$F, MATCH(1, (VALUE(LEFT(fesp!$A:$A,6))=VALUE(LEFT(B4,6)))*(fesp!$C:$C=C4), 0)), "")} -> 892 | P4: {=IFERROR(INDEX(fesp!$G:$G, MATCH(1, (VALUE(LEFT(fesp!$A:$A,6))=VALUE(LEFT(B4,6)))*(fesp!$C:$C=C4), 0)), "")} -> 4765730 | Q4: {=IFERROR(INDEX(fesp!$H:$H, MATCH(1, (VALUE(LEFT(fesp!$A:$A,6))=VALUE(LEFT(B4,6)))*(fesp!$C:$C=C4), 0)), "")} -> 25 | R4: {=IFERROR(INDEX(fesp!$I:$I, MATCH(1, (VALUE(LEFT(fesp!$A:$A,6))=VALUE(LEFT(B4,6)))*(fesp!$C:$C=C4), 0)), "")} -> 24180 | S4: {=IFERROR(INDEX(fesp!$J:$J, MATCH(1, (VALUE(LEFT(fesp!$A:$A,6))=VALUE(LEFT(B4,6)))*(fesp!$C:$C=C4), 0)), "")} -> 85781
A5: Porto Velho (RO) | B5: 1100205 | C5: 2018 | D5: {=IFERROR(INDEX(fesp!$D:$D, MATCH(1, (VALUE(LEFT(fesp!$A:$A,6))=VALUE(LEFT(B5,6)))*(fesp!$C:$C=C5), 0)), "")} -> 0 | E5: {=IFERROR(INDEX(ft_medicos_clinicos!$C:$C, MATCH(1, (VALUE(LEFT(ft_medicos_clinicos!$A:$A,6))=VALUE(LEFT(B5,6)))*(ft_medicos_clinicos!$B:$B=C5), 0)), "")} -> 324 | F5: {=IFERROR(INDEX(ft_enfermeiros!$C:$C, MATCH(1, (VALUE(LEFT(ft_enfermeiros!$A:$A,6))=VALUE(LEFT(B5,6)))*(ft_enfermeiros!$B:$B=C5), 0)), "")} -> 706 | G5: {=IFERROR(INDEX(ft_equipes_acs!$C:$C, MATCH(1, (VALUE(LEFT(ft_equipes_acs!$A:$A,6))=VALUE(LEFT(B5,6)))*(ft_equipes_acs!$B:$B=C5), 0)), "")} -> - | H5: {=IFERROR(INDEX(ci_leitos_internacao!$C:$C, MATCH(1, (VALUE(LEFT(ci_leitos_internacao!$A:$A,6))=VALUE(LEFT(B5,6)))*(ci_leitos_internacao!$B:$B=C5), 0)), "")} -> 1772 | I5: {=IFERROR(INDEX(ci_hospitais_internacao!$C:$C, MATCH(1, (VALUE(LEFT(ci_hospitais_internacao!$A:$A,6))=VALUE(LEFT(B5,6)))*(ci_hospitais_internacao!$B:$B=C5), 0)), "")} -> 6 | J5: {=IFERROR(INDEX(ci_pa_clinico!$C:$C, MATCH(1, (VALUE(LEFT(ci_pa_clinico!$A:$A,6))=VALUE(LEFT(B5,6)))*(ci_pa_clinico!$B:$B=C5), 0)), "")} -> 6 | K5: {=IFERROR(INDEX(aps_equipes_esf!$C:$C, MATCH(1, (VALUE(LEFT(aps_equipes_esf!$A:$A,6))=VALUE(LEFT(B5,6)))*(aps_equipes_esf!$B:$B=C5), 0)), "")} -> 32 | L5: {=IFERROR(INDEX(casos!$C:$C, MATCH(1, (VALUE(LEFT(casos!$A:$A,6))=VALUE(LEFT(B5,6)))*(casos!$B:$B=C5), 0)), "")} -> 114 | M5: {=IFERROR(INDEX(srag!$D:$D, MATCH(1, (VALUE(LEFT(srag!$A:$A,6))=VALUE(LEFT(B5,6)))*(srag!$C:$C=C5), 0)), "")} -> 19 | N5: {=IFERROR(INDEX(fesp!$E:$E, MATCH(1, (VALUE(LEFT(fesp!$A:$A,6))=VALUE(LEFT(B5,6)))*(fesp!$C:$C=C5), 0)), "")} -> 96 | O5: {=IFERROR(INDEX(fesp!$F:$F, MATCH(1, (VALUE(LEFT(fesp!$A:$A,6))=VALUE(LEFT(B5,6)))*(fesp!$C:$C=C5), 0)), "")} -> 1480 | P5: {=IFERROR(INDEX(fesp!$G:$G, MATCH(1, (VALUE(LEFT(fesp!$A:$A,6))=VALUE(LEFT(B5,6)))*(fesp!$C:$C=C5), 0)), "")} -> 5243163 | Q5: {=IFERROR(INDEX(fesp!$H:$H, MATCH(1, (VALUE(LEFT(fesp!$A:$A,6))=VALUE(LEFT(B5,6)))*(fesp!$C:$C=C5), 0)), "")} -> 17 | R5: {=IFERROR(INDEX(fesp!$I:$I, MATCH(1, (VALUE(LEFT(fesp!$A:$A,6))=VALUE(LEFT(B5,6)))*(fesp!$C:$C=C5), 0)), "")} -> 7469 | S5: {=IFERROR(INDEX(fesp!$J:$J, MATCH(1, (VALUE(LEFT(fesp!$A:$A,6))=VALUE(LEFT(B5,6)))*(fesp!$C:$C=C5), 0)), "")} -> 1365
A6: Porto Velho (RO) | B6: 1100205 | C6: 2019 | D6: {=IFERROR(INDEX(fesp!$D:$D, MATCH(1, (VALUE(LEFT(fesp!$A:$A,6))=VALUE(LEFT(B6,6)))*(fesp!$C:$C=C6), 0)), "")} -> 0 | E6: {=IFERROR(INDEX(ft_medicos_clinicos!$C:$C, MATCH(1, (VALUE(LEFT(ft_medicos_clinicos!$A:$A,6))=VALUE(LEFT(B6,6)))*(ft_medicos_clinicos!$B:$B=C6), 0)), "")} -> 328 | F6: {=IFERROR(INDEX(ft_enfermeiros!$C:$C, MATCH(1, (VALUE(LEFT(ft_enfermeiros!$A:$A,6))=VALUE(LEFT(B6,6)))*(ft_enfermeiros!$B:$B=C6), 0)), "")} -> 785 | G6: {=IFERROR(INDEX(ft_equipes_acs!$C:$C, MATCH(1, (VALUE(LEFT(ft_equipes_acs!$A:$A,6))=VALUE(LEFT(B6,6)))*(ft_equipes_acs!$B:$B=C6), 0)), "")} -> - | H6: {=IFERROR(INDEX(ci_leitos_internacao!$C:$C, MATCH(1, (VALUE(LEFT(ci_leitos_internacao!$A:$A,6))=VALUE(LEFT(B6,6)))*(ci_leitos_internacao!$B:$B=C6), 0)), "")} -> 1851 | I6: {=IFERROR(INDEX(ci_hospitais_internacao!$C:$C, MATCH(1, (VALUE(LEFT(ci_hospitais_internacao!$A:$A,6))=VALUE(LEFT(B6,6)))*(ci_hospitais_internacao!$B:$B=C6), 0)), "")} -> 8 | J6: {=IFERROR(INDEX(ci_pa_clinico!$C:$C, MATCH(1, (VALUE(LEFT(ci_pa_clinico!$A:$A,6))=VALUE(LEFT(B6,6)))*(ci_pa_clinico!$B:$B=C6), 0)), "")} -> 6 | K6: {=IFERROR(INDEX(aps_equipes_esf!$C:$C, MATCH(1, (VALUE(LEFT(aps_equipes_esf!$A:$A,6))=VALUE(LEFT(B6,6)))*(aps_equipes_esf!$B:$B=C6), 0)), "")} -> 28 | L6: {=IFERROR(INDEX(casos!$C:$C, MATCH(1, (VALUE(LEFT(casos!$A:$A,6))=VALUE(LEFT(B6,6)))*(casos!$B:$B=C6), 0)), "")} -> 181 | M6: {=IFERROR(INDEX(srag!$D:$D, MATCH(1, (VALUE(LEFT(srag!$A:$A,6))=VALUE(LEFT(B6,6)))*(srag!$C:$C=C6), 0)), "")} -> 63 | N6: {=IFERROR(INDEX(fesp!$E:$E, MATCH(1, (VALUE(LEFT(fesp!$A:$A,6))=VALUE(LEFT(B6,6)))*(fesp!$C:$C=C6), 0)), "")} -> 116 | O6: {=IFERROR(INDEX(fesp!$F:$F, MATCH(1, (VALUE(LEFT(fesp!$A:$A,6))=VALUE(LEFT(B6,6)))*(fesp!$C:$C=C6), 0)), "")} -> 2950 | P6: {=IFERROR(INDEX(fesp!$G:$G, MATCH(1, (VALUE(LEFT(fesp!$A:$A,6))=VALUE(LEFT(B6,6)))*(fesp!$C:$C=C6), 0)), "")} -> 5397213 | Q6: {=IFERROR(INDEX(fesp!$H:$H, MATCH(1, (VALUE(LEFT(fesp!$A:$A,6))=VALUE(LEFT(B6,6)))*(fesp!$C:$C=C6), 0)), "")} -> 26 | R6: {=IFERROR(INDEX(fesp!$I:$I, MATCH(1, (VALUE(LEFT(fesp!$A:$A,6))=VALUE(LEFT(B6,6)))*(fesp!$C:$C=C6), 0)), "")} -> 6023 | S6: {=IFERROR(INDEX(fesp!$J:$J, MATCH(1, (VALUE(LEFT(fesp!$A:$A,6))=VALUE(LEFT(B6,6)))*(fesp!$C:$C=C6), 0)), "")} -> 210
A7: Porto Velho (RO) | B7: 1100205 | C7: 2020 | D7: {=IFERROR(INDEX(fesp!$D:$D, MATCH(1, (VALUE(LEFT(fesp!$A:$A,6))=VALUE(LEFT(B7,6)))*(fesp!$C:$C=C7), 0)), "")} -> 0 | E7: {=IFERROR(INDEX(ft_medicos_clinicos!$C:$C, MATCH(1, (VALUE(LEFT(ft_medicos_clinicos!$A:$A,6))=VALUE(LEFT(B7,6)))*(ft_medicos_clinicos!$B:$B=C7), 0)), "")} -> 421 | F7: {=IFERROR(INDEX(ft_enfermeiros!$C:$C, MATCH(1, (VALUE(LEFT(ft_enfermeiros!$A:$A,6))=VALUE(LEFT(B7,6)))*(ft_enfermeiros!$B:$B=C7), 0)), "")} -> 1041 | G7: {=IFERROR(INDEX(ft_equipes_acs!$C:$C, MATCH(1, (VALUE(LEFT(ft_equipes_acs!$A:$A,6))=VALUE(LEFT(B7,6)))*(ft_equipes_acs!$B:$B=C7), 0)), "")} -> - | H7: {=IFERROR(INDEX(ci_leitos_internacao!$C:$C, MATCH(1, (VALUE(LEFT(ci_leitos_internacao!$A:$A,6))=VALUE(LEFT(B7,6)))*(ci_leitos_internacao!$B:$B=C7), 0)), "")} -> 1871 | I7: {=IFERROR(INDEX(ci_hospitais_internacao!$C:$C, MATCH(1, (VALUE(LEFT(ci_hospitais_internacao!$A:$A,6))=VALUE(LEFT(B7,6)))*(ci_hospitais_internacao!$B:$B=C7), 0)), "")} -> 7 | J7: {=IFERROR(INDEX(ci_pa_clinico!$C:$C, MATCH(1, (VALUE(LEFT(ci_pa_clinico!$A:$A,6))=VALUE(LEFT(B7,6)))*(ci_pa_clinico!$B:$B=C7), 0)), "")} -> 6 | K7: {=IFERROR(INDEX(aps_equipes_esf!$C:$C, MATCH(1, (VALUE(LEFT(aps_equipes_esf!$A:$A,6))=VALUE(LEFT(B7,6)))*(aps_equipes_esf!$B:$B=C7), 0)), "")} -> 3 | L7: {=IFERROR(INDEX(casos!$C:$C, MATCH(1, (VALUE(LEFT(casos!$A:$A,6))=VALUE(LEFT(B7,6)))*(casos!$B:$B=C7), 0)), "")} -> 309 | M7: {=IFERROR(INDEX(srag!$D:$D, MATCH(1, (VALUE(LEFT(srag!$A:$A,6))=VALUE(LEFT(B7,6)))*(srag!$C:$C=C7), 0)), "")} -> 3483 | N7: {=IFERROR(INDEX(fesp!$E:$E, MATCH(1, (VALUE(LEFT(fesp!$A:$A,6))=VALUE(LEFT(B7,6)))*(fesp!$C:$C=C7), 0)), "")} -> 227 | O7: {=IFERROR(INDEX(fesp!$F:$F, MATCH(1, (VALUE(LEFT(fesp!$A:$A,6))=VALUE(LEFT(B7,6)))*(fesp!$C:$C=C7), 0)), "")} -> 1155 | P7: {=IFERROR(INDEX(fesp!$G:$G, MATCH(1, (VALUE(LEFT(fesp!$A:$A,6))=VALUE(LEFT(B7,6)))*(fesp!$C:$C=C7), 0)), "")} -> 4105324 | Q7: {=IFERROR(INDEX(fesp!$H:$H, MATCH(1, (VALUE(LEFT(fesp!$A:$A,6))=VALUE(LEFT(B7,6)))*(fesp!$C:$C=C7), 0)), "")} -> 71 | R7: {=IFERROR(INDEX(fesp!$I:$I, MATCH(1, (VALUE(LEFT(fesp!$A:$A,6))=VALUE(LEFT(B7,6)))*(fesp!$C:$C=C7), 0)), "")} -> 3322 | S7: {=IFERROR(INDEX(fesp!$J:$J, MATCH(1, (VALUE(LEFT(fesp!$A:$A,6))=VALUE(LEFT(B7,6)))*(fesp!$C:$C=C7), 0)), "")} -> 0
A8: Porto Velho (RO) | B8: 1100205 | C8: 2021 | D8: {=IFERROR(INDEX(fesp!$D:$D, MATCH(1, (VALUE(LEFT(fesp!$A:$A,6))=VALUE(LEFT(B8,6)))*(fesp!$C:$C=C8), 0)), "")} -> 0 | E8: {=IFERROR(INDEX(ft_medicos_clinicos!$C:$C, MATCH(1, (VALUE(LEFT(ft_medicos_clinicos!$A:$A,6))=VALUE(LEFT(B8,6)))*(ft_medicos_clinicos!$B:$B=C8), 0)), "")} -> 467 | F8: {=IFERROR(INDEX(ft_enfermeiros!$C:$C, MATCH(1, (VALUE(LEFT(ft_enfermeiros!$A:$A,6))=VALUE(LEFT(B8,6)))*(ft_enfermeiros!$B:$B=C8), 0)), "")} -> 1078 | G8: {=IFERROR(INDEX(ft_equipes_acs!$C:$C, MATCH(1, (VALUE(LEFT(ft_equipes_acs!$A:$A,6))=VALUE(LEFT(B8,6)))*(ft_equipes_acs!$B:$B=C8), 0)), "")} -> - | H8: {=IFERROR(INDEX(ci_leitos_internacao!$C:$C, MATCH(1, (VALUE(LEFT(ci_leitos_internacao!$A:$A,6))=VALUE(LEFT(B8,6)))*(ci_leitos_internacao!$B:$B=C8), 0)), "")} -> 1887 | I8: {=IFERROR(INDEX(ci_hospitais_internacao!$C:$C, MATCH(1, (VALUE(LEFT(ci_hospitais_internacao!$A:$A,6))=VALUE(LEFT(B8,6)))*(ci_hospitais_internacao!$B:$B=C8), 0)), "")} -> 8 | J8: {=IFERROR(INDEX(ci_pa_clinico!$C:$C, MATCH(1, (VALUE(LEFT(ci_pa_clinico!$A:$A,6))=VALUE(LEFT(B8,6)))*(ci_pa_clinico!$B:$B=C8), 0)), "")} -> 6 | K8: {=IFERROR(INDEX(aps_equipes_esf!$C:$C, MATCH(1, (VALUE(LEFT(aps_equipes_esf!$A:$A,6))=VALUE(LEFT(B8,6)))*(aps_equipes_esf!$B:$B=C8), 0)), "")} -> 2 | L8: {=IFERROR(INDEX(casos!$C:$C, MATCH(1, (VALUE(LEFT(casos!$A:$A,6))=VALUE(LEFT(B8,6)))*(casos!$B:$B=C8), 0)), "")} -> 212 | M8: {=IFERROR(INDEX(srag!$D:$D, MATCH(1, (VALUE(LEFT(srag!$A:$A,6))=VALUE(LEFT(B8,6)))*(srag!$C:$C=C8), 0)), "")} -> 6682 | N8: {=IFERROR(INDEX(fesp!$E:$E, MATCH(1, (VALUE(LEFT(fesp!$A:$A,6))=VALUE(LEFT(B8,6)))*(fesp!$C:$C=C8), 0)), "")} -> 277 | O8: {=IFERROR(INDEX(fesp!$F:$F, MATCH(1, (VALUE(LEFT(fesp!$A:$A,6))=VALUE(LEFT(B8,6)))*(fesp!$C:$C=C8), 0)), "")} -> 1441 | P8: {=IFERROR(INDEX(fesp!$G:$G, MATCH(1, (VALUE(LEFT(fesp!$A:$A,6))=VALUE(LEFT(B8,6)))*(fesp!$C:$C=C8), 0)), "")} -> 5205099 | Q8: {=IFERROR(INDEX(fesp!$H:$H, MATCH(1, (VALUE(LEFT(fesp!$A:$A,6))=VALUE(LEFT(B8,6)))*(fesp!$C:$C=C8), 0)), "")} -> 53 | R8: {=IFERROR(INDEX(fesp!$I:$I, MATCH(1, (VALUE(LEFT(fesp!$A:$A,6))=VALUE(LEFT(B8,6)))*(fesp!$C:$C=C8), 0)), "")} -> 1893 | S8: {=IFERROR(INDEX(fesp!$J:$J, MATCH(1, (VALUE(LEFT(fesp!$A:$A,6))=VALUE(LEFT(B8,6)))*(fesp!$C:$C=C8), 0)), "")} -> 0
A9: Porto Velho (RO) | B9: 1100205 | C9: 2022 | D9: {=IFERROR(INDEX(fesp!$D:$D, MATCH(1, (VALUE(LEFT(fesp!$A:$A,6))=VALUE(LEFT(B9,6)))*(fesp!$C:$C=C9), 0)), "")} -> 460434 | E9: {=IFERROR(INDEX(ft_medicos_clinicos!$C:$C, MATCH(1, (VALUE(LEFT(ft_medicos_clinicos!$A:$A,6))=VALUE(LEFT(B9,6)))*(ft_medicos_clinicos!$B:$B=C9), 0)), "")} -> 460 | F9: {=IFERROR(INDEX(ft_enfermeiros!$C:$C, MATCH(1, (VALUE(LEFT(ft_enfermeiros!$A:$A,6))=VALUE(LEFT(B9,6)))*(ft_enfermeiros!$B:$B=C9), 0)), "")} -> 1090 | G9: {=IFERROR(INDEX(ft_equipes_acs!$C:$C, MATCH(1, (VALUE(LEFT(ft_equipes_acs!$A:$A,6))=VALUE(LEFT(B9,6)))*(ft_equipes_acs!$B:$B=C9), 0)), "")} -> - | H9: {=IFERROR(INDEX(ci_leitos_internacao!$C:$C, MATCH(1, (VALUE(LEFT(ci_leitos_internacao!$A:$A,6))=VALUE(LEFT(B9,6)))*(ci_leitos_internacao!$B:$B=C9), 0)), "")} -> 1899 | I9: {=IFERROR(INDEX(ci_hospitais_internacao!$C:$C, MATCH(1, (VALUE(LEFT(ci_hospitais_internacao!$A:$A,6))=VALUE(LEFT(B9,6)))*(ci_hospitais_internacao!$B:$B=C9), 0)), "")} -> 7 | J9: {=IFERROR(INDEX(ci_pa_clinico!$C:$C, MATCH(1, (VALUE(LEFT(ci_pa_clinico!$A:$A,6))=VALUE(LEFT(B9,6)))*(ci_pa_clinico!$B:$B=C9), 0)), "")} -> 6 | K9: {=IFERROR(INDEX(aps_equipes_esf!$C:$C, MATCH(1, (VALUE(LEFT(aps_equipes_esf!$A:$A,6))=VALUE(LEFT(B9,6)))*(aps_equipes_esf!$B:$B=C9), 0)), "")} -> 2 | L9: {=IFERROR(INDEX(casos!$C:$C, MATCH(1, (VALUE(LEFT(casos!$A:$A,6))=VALUE(LEFT(B9,6)))*(casos!$B:$B=C9), 0)), "")} -> 2021 | M9: {=IFERROR(INDEX(srag!$D:$D, MATCH(1, (VALUE(LEFT(srag!$A:$A,6))=VALUE(LEFT(B9,6)))*(srag!$C:$C=C9), 0)), "")} -> 1270 | N9: {=IFERROR(INDEX(fesp!$E:$E, MATCH(1, (VALUE(LEFT(fesp!$A:$A,6))=VALUE(LEFT(B9,6)))*(fesp!$C:$C=C9), 0)), "")} -> 153 | O9: {=IFERROR(INDEX(fesp!$F:$F, MATCH(1, (VALUE(LEFT(fesp!$A:$A,6))=VALUE(LEFT(B9,6)))*(fesp!$C:$C=C9), 0)), "")} -> 1874 | P9: {=IFERROR(INDEX(fesp!$G:$G, MATCH(1, (VALUE(LEFT(fesp!$A:$A,6))=VALUE(LEFT(B9,6)))*(fesp!$C:$C=C9), 0)), "")} -> 5880989 | Q9: {=IFERROR(INDEX(fesp!$H:$H, MATCH(1, (VALUE(LEFT(fesp!$A:$A,6))=VALUE(LEFT(B9,6)))*(fesp!$C:$C=C9), 0)), "")} -> 51 | R9: {=IFERROR(INDEX(fesp!$I:$I, MATCH(1, (VALUE(LEFT(fesp!$A:$A,6))=VALUE(LEFT(B9,6)))*(fesp!$C:$C=C9), 0)), "")} -> 4957 | S9: {=IFERROR(INDEX(fesp!$J:$J, MATCH(1, (VALUE(LEFT(fesp!$A:$A,6))=VALUE(LEFT(B9,6)))*(fesp!$C:$C=C9), 0)), "")} -> 1
A10: Porto Velho (RO) | B10: 1100205 | C10: 2023 | D10: {=IFERROR(INDEX(fesp!$D:$D, MATCH(1, (VALUE(LEFT(fesp!$A:$A,6))=VALUE(LEFT(B10,6)))*(fesp!$C:$C=C10), 0)), "")} -> 0 | E10: {=IFERROR(INDEX(ft_medicos_clinicos!$C:$C, MATCH(1, (VALUE(LEFT(ft_medicos_clinicos!$A:$A,6))=VALUE(LEFT(B10,6)))*(ft_medicos_clinicos!$B:$B=C10), 0)), "")} -> 474 | F10: {=IFERROR(INDEX(ft_enfermeiros!$C:$C, MATCH(1, (VALUE(LEFT(ft_enfermeiros!$A:$A,6))=VALUE(LEFT(B10,6)))*(ft_enfermeiros!$B:$B=C10), 0)), "")} -> 1179 | G10: {=IFERROR(INDEX(ft_equipes_acs!$C:$C, MATCH(1, (VALUE(LEFT(ft_equipes_acs!$A:$A,6))=VALUE(LEFT(B10,6)))*(ft_equipes_acs!$B:$B=C10), 0)), "")} -> - | H10: {=IFERROR(INDEX(ci_leitos_internacao!$C:$C, MATCH(1, (VALUE(LEFT(ci_leitos_internacao!$A:$A,6))=VALUE(LEFT(B10,6)))*(ci_leitos_internacao!$B:$B=C10), 0)), "")} -> 1892 | I10: {=IFERROR(INDEX(ci_hospitais_internacao!$C:$C, MATCH(1, (VALUE(LEFT(ci_hospitais_internacao!$A:$A,6))=VALUE(LEFT(B10,6)))*(ci_hospitais_internacao!$B:$B=C10), 0)), "")} -> 7 | J10: {=IFERROR(INDEX(ci_pa_clinico!$C:$C, MATCH(1, (VALUE(LEFT(ci_pa_clinico!$A:$A,6))=VALUE(LEFT(B10,6)))*(ci_pa_clinico!$B:$B=C10), 0)), "")} -> 6 | K10: {=IFERROR(INDEX(aps_equipes_esf!$C:$C, MATCH(1, (VALUE(LEFT(aps_equipes_esf!$A:$A,6))=VALUE(LEFT(B10,6)))*(aps_equipes_esf!$B:$B=C10), 0)), "")} -> 2 | L10: {=IFERROR(INDEX(casos!$C:$C, MATCH(1, (VALUE(LEFT(casos!$A:$A,6))=VALUE(LEFT(B10,6)))*(casos!$B:$B=C10), 0)), "")} -> 1160 | M10: {=IFERROR(INDEX(srag!$D:$D, MATCH(1, (VALUE(LEFT(srag!$A:$A,6))=VALUE(LEFT(B10,6)))*(srag!$C:$C=C10), 0)), "")} -> 642 | N10: {=IFERROR(INDEX(fesp!$E:$E, MATCH(1, (VALUE(LEFT(fesp!$A:$A,6))=VALUE(LEFT(B10,6)))*(fesp!$C:$C=C10), 0)), "")} -> 173 | O10: {=IFERROR(INDEX(fesp!$F:$F, MATCH(1, (VALUE(LEFT(fesp!$A:$A,6))=VALUE(LEFT(B10,6)))*(fesp!$C:$C=C10), 0)), "")} -> 1880 | P10: {=IFERROR(INDEX(fesp!$G:$G, MATCH(1, (VALUE(LEFT(fesp!$A:$A,6))=VALUE(LEFT(B10,6)))*(fesp!$C:$C=C10), 0)), "")} -> 5655048 | Q10: {=IFERROR(INDEX(fesp!$H:$H, MATCH(1, (VALUE(LEFT(fesp!$A:$A,6))=VALUE(LEFT(B10,6)))*(fesp!$C:$C=C10), 0)), "")} -> 28 | R10: {=IFERROR(INDEX(fesp!$I:$I, MATCH(1, (VALUE(LEFT(fesp!$A:$A,6))=VALUE(LEFT(B10,6)))*(fesp!$C:$C=C10), 0)), "")} -> 5489 | S10: {=IFERROR(INDEX(fesp!$J:$J, MATCH(1, (VALUE(LEFT(fesp!$A:$A,6))=VALUE(LEFT(B10,6)))*(fesp!$C:$C=C10), 0)), "")} -> 0
A11: Porto Velho (RO) | B11: 1100205 | C11: 2024 | D11: {=IFERROR(INDEX(fesp!$D:$D, MATCH(1, (VALUE(LEFT(fesp!$A:$A,6))=VALUE(LEFT(B11,6)))*(fesp!$C:$C=C11), 0)), "")} -> 0 | E11: {=IFERROR(INDEX(ft_medicos_clinicos!$C:$C, MATCH(1, (VALUE(LEFT(ft_medicos_clinicos!$A:$A,6))=VALUE(LEFT(B11,6)))*(ft_medicos_clinicos!$B:$B=C11), 0)), "")} -> 550 | F11: {=IFERROR(INDEX(ft_enfermeiros!$C:$C, MATCH(1, (VALUE(LEFT(ft_enfermeiros!$A:$A,6))=VALUE(LEFT(B11,6)))*(ft_enfermeiros!$B:$B=C11), 0)), "")} -> 1130 | G11: {=IFERROR(INDEX(ft_equipes_acs!$C:$C, MATCH(1, (VALUE(LEFT(ft_equipes_acs!$A:$A,6))=VALUE(LEFT(B11,6)))*(ft_equipes_acs!$B:$B=C11), 0)), "")} -> - | H11: {=IFERROR(INDEX(ci_leitos_internacao!$C:$C, MATCH(1, (VALUE(LEFT(ci_leitos_internacao!$A:$A,6))=VALUE(LEFT(B11,6)))*(ci_leitos_internacao!$B:$B=C11), 0)), "")} -> 1909 | I11: {=IFERROR(INDEX(ci_hospitais_internacao!$C:$C, MATCH(1, (VALUE(LEFT(ci_hospitais_internacao!$A:$A,6))=VALUE(LEFT(B11,6)))*(ci_hospitais_internacao!$B:$B=C11), 0)), "")} -> 9 | J11: {=IFERROR(INDEX(ci_pa_clinico!$C:$C, MATCH(1, (VALUE(LEFT(ci_pa_clinico!$A:$A,6))=VALUE(LEFT(B11,6)))*(ci_pa_clinico!$B:$B=C11), 0)), "")} -> 6 | K11: {=IFERROR(INDEX(aps_equipes_esf!$C:$C, MATCH(1, (VALUE(LEFT(aps_equipes_esf!$A:$A,6))=VALUE(LEFT(B11,6)))*(aps_equipes_esf!$B:$B=C11), 0)), "")} -> 2 | L11: {=IFERROR(INDEX(casos!$C:$C, MATCH(1, (VALUE(LEFT(casos!$A:$A,6))=VALUE(LEFT(B11,6)))*(casos!$B:$B=C11), 0)), "")} -> 613 | M11: {=IFERROR(INDEX(srag!$D:$D, MATCH(1, (VALUE(LEFT(srag!$A:$A,6))=VALUE(LEFT(B11,6)))*(srag!$C:$C=C11), 0)), "")} -> 719 | N11: {=IFERROR(INDEX(fesp!$E:$E, MATCH(1, (VALUE(LEFT(fesp!$A:$A,6))=VALUE(LEFT(B11,6)))*(fesp!$C:$C=C11), 0)), "")} -> 110 | O11: {=IFERROR(INDEX(fesp!$F:$F, MATCH(1, (VALUE(LEFT(fesp!$A:$A,6))=VALUE(LEFT(B11,6)))*(fesp!$C:$C=C11), 0)), "")} -> 2923 | P11: {=IFERROR(INDEX(fesp!$G:$G, MATCH(1, (VALUE(LEFT(fesp!$A:$A,6))=VALUE(LEFT(B11,6)))*(fesp!$C:$C=C11), 0)), "")} -> 6506314 | Q11: {=IFERROR(INDEX(fesp!$H:$H, MATCH(1, (VALUE(LEFT(fesp!$A:$A,6))=VALUE(LEFT(B11,6)))*(fesp!$C:$C=C11), 0)), "")} -> 20 | R11: {=IFERROR(INDEX(fesp!$I:$I, MATCH(1, (VALUE(LEFT(fesp!$A:$A,6))=VALUE(LEFT(B11,6)))*(fesp!$C:$C=C11), 0)), "")} -> 5907 | S11: {=IFERROR(INDEX(fesp!$J:$J, MATCH(1, (VALUE(LEFT(fesp!$A:$A,6))=VALUE(LEFT(B11,6)))*(fesp!$C:$C=C11), 0)), "")} -> 1
A12: Porto Velho (RO) | B12: 1100205 | C12: 2025 | D12: {=IFERROR(INDEX(fesp!$D:$D, MATCH(1, (VALUE(LEFT(fesp!$A:$A,6))=VALUE(LEFT(B12,6)))*(fesp!$C:$C=C12), 0)), "")} -> 0 | E12: {=IFERROR(INDEX(ft_medicos_clinicos!$C:$C, MATCH(1, (VALUE(LEFT(ft_medicos_clinicos!$A:$A,6))=VALUE(LEFT(B12,6)))*(ft_medicos_clinicos!$B:$B=C12), 0)), "")} -> 607 | F12: {=IFERROR(INDEX(ft_enfermeiros!$C:$C, MATCH(1, (VALUE(LEFT(ft_enfermeiros!$A:$A,6))=VALUE(LEFT(B12,6)))*(ft_enfermeiros!$B:$B=C12), 0)), "")} -> 1145 | G12: {=IFERROR(INDEX(ft_equipes_acs!$C:$C, MATCH(1, (VALUE(LEFT(ft_equipes_acs!$A:$A,6))=VALUE(LEFT(B12,6)))*(ft_equipes_acs!$B:$B=C12), 0)), "")} -> - | H12: {=IFERROR(INDEX(ci_leitos_internacao!$C:$C, MATCH(1, (VALUE(LEFT(ci_leitos_internacao!$A:$A,6))=VALUE(LEFT(B12,6)))*(ci_leitos_internacao!$B:$B=C12), 0)), "")} -> 1967 | I12: {=IFERROR(INDEX(ci_hospitais_internacao!$C:$C, MATCH(1, (VALUE(LEFT(ci_hospitais_internacao!$A:$A,6))=VALUE(LEFT(B12,6)))*(ci_hospitais_internacao!$B:$B=C12), 0)), "")} -> 12 | J12: {=IFERROR(INDEX(ci_pa_clinico!$C:$C, MATCH(1, (VALUE(LEFT(ci_pa_clinico!$A:$A,6))=VALUE(LEFT(B12,6)))*(ci_pa_clinico!$B:$B=C12), 0)), "")} -> 6 | K12: {=IFERROR(INDEX(aps_equipes_esf!$C:$C, MATCH(1, (VALUE(LEFT(aps_equipes_esf!$A:$A,6))=VALUE(LEFT(B12,6)))*(aps_equipes_esf!$B:$B=C12), 0)), "")} -> 2 | L12: {=IFERROR(INDEX(casos!$C:$C, MATCH(1, (VALUE(LEFT(casos!$A:$A,6))=VALUE(LEFT(B12,6)))*(casos!$B:$B=C12), 0)), "")} -> 211 | M12: {=IFERROR(INDEX(srag!$D:$D, MATCH(1, (VALUE(LEFT(srag!$A:$A,6))=VALUE(LEFT(B12,6)))*(srag!$C:$C=C12), 0)), "")} -> 812 | N12: {=IFERROR(INDEX(fesp!$E:$E, MATCH(1, (VALUE(LEFT(fesp!$A:$A,6))=VALUE(LEFT(B12,6)))*(fesp!$C:$C=C12), 0)), "")} -> 79 | O12: {=IFERROR(INDEX(fesp!$F:$F, MATCH(1, (VALUE(LEFT(fesp!$A:$A,6))=VALUE(LEFT(B12,6)))*(fesp!$C:$C=C12), 0)), "")} -> 6053 | P12: {=IFERROR(INDEX(fesp!$G:$G, MATCH(1, (VALUE(LEFT(fesp!$A:$A,6))=VALUE(LEFT(B12,6)))*(fesp!$C:$C=C12), 0)), "")} -> 5348012 | Q12: {=IFERROR(INDEX(fesp!$H:$H, MATCH(1, (VALUE(LEFT(fesp!$A:$A,6))=VALUE(LEFT(B12,6)))*(fesp!$C:$C=C12), 0)), "")} -> 34 | R12: {=IFERROR(INDEX(fesp!$I:$I, MATCH(1, (VALUE(LEFT(fesp!$A:$A,6))=VALUE(LEFT(B12,6)))*(fesp!$C:$C=C12), 0)), "")} -> 1401 | S12: {=IFERROR(INDEX(fesp!$J:$J, MATCH(1, (VALUE(LEFT(fesp!$A:$A,6))=VALUE(LEFT(B12,6)))*(fesp!$C:$C=C12), 0)), "")} -> 0
A13: Manaus (AM) | B13: 1302603 | C13: 2015 | D13: {=IFERROR(INDEX(fesp!$D:$D, MATCH(1, (VALUE(LEFT(fesp!$A:$A,6))=VALUE(LEFT(B13,6)))*(fesp!$C:$C=C13), 0)), "")} -> 2057711 | E13: {=IFERROR(INDEX(ft_medicos_clinicos!$C:$C, MATCH(1, (VALUE(LEFT(ft_medicos_clinicos!$A:$A,6))=VALUE(LEFT(B13,6)))*(ft_medicos_clinicos!$B:$B=C13), 0)), "")} -> 660 | F13: {=IFERROR(INDEX(ft_enfermeiros!$C:$C, MATCH(1, (VALUE(LEFT(ft_enfermeiros!$A:$A,6))=VALUE(LEFT(B13,6)))*(ft_enfermeiros!$B:$B=C13), 0)), "")} -> 1521 | G13: {=IFERROR(INDEX(ft_equipes_acs!$C:$C, MATCH(1, (VALUE(LEFT(ft_equipes_acs!$A:$A,6))=VALUE(LEFT(B13,6)))*(ft_equipes_acs!$B:$B=C13), 0)), "")} | H13: {=IFERROR(INDEX(ci_leitos_internacao!$C:$C, MATCH(1, (VALUE(LEFT(ci_leitos_internacao!$A:$A,6))=VALUE(LEFT(B13,6)))*(ci_leitos_internacao!$B:$B=C13), 0)), "")} -> 3425 | I13: {=IFERROR(INDEX(ci_hospitais_internacao!$C:$C, MATCH(1, (VALUE(LEFT(ci_hospitais_internacao!$A:$A,6))=VALUE(LEFT(B13,6)))*(ci_hospitais_internacao!$B:$B=C13), 0)), "")} -> 14 | J13: {=IFERROR(INDEX(ci_pa_clinico!$C:$C, MATCH(1, (VALUE(LEFT(ci_pa_clinico!$A:$A,6))=VALUE(LEFT(B13,6)))*(ci_pa_clinico!$B:$B=C13), 0)), "")} | K13: {=IFERROR(INDEX(aps_equipes_esf!$C:$C, MATCH(1, (VALUE(LEFT(aps_equipes_esf!$A:$A,6))=VALUE(LEFT(B13,6)))*(aps_equipes_esf!$B:$B=C13), 0)), "")} -> 111 | L13: {=IFERROR(INDEX(casos!$C:$C, MATCH(1, (VALUE(LEFT(casos!$A:$A,6))=VALUE(LEFT(B13,6)))*(casos!$B:$B=C13), 0)), "")} -> 1620 | M13: {=IFERROR(INDEX(srag!$D:$D, MATCH(1, (VALUE(LEFT(srag!$A:$A,6))=VALUE(LEFT(B13,6)))*(srag!$C:$C=C13), 0)), "")} -> 36 | N13: {=IFERROR(INDEX(fesp!$E:$E, MATCH(1, (VALUE(LEFT(fesp!$A:$A,6))=VALUE(LEFT(B13,6)))*(fesp!$C:$C=C13), 0)), "")} -> 649 | O13: {=IFERROR(INDEX(fesp!$F:$F, MATCH(1, (VALUE(LEFT(fesp!$A:$A,6))=VALUE(LEFT(B13,6)))*(fesp!$C:$C=C13), 0)), "")} -> 18779 | P13: {=IFERROR(INDEX(fesp!$G:$G, MATCH(1, (VALUE(LEFT(fesp!$A:$A,6))=VALUE(LEFT(B13,6)))*(fesp!$C:$C=C13), 0)), "")} -> 15325905 | Q13: {=IFERROR(INDEX(fesp!$H:$H, MATCH(1, (VALUE(LEFT(fesp!$A:$A,6))=VALUE(LEFT(B13,6)))*(fesp!$C:$C=C13), 0)), "")} -> 471 | R13: {=IFERROR(INDEX(fesp!$I:$I, MATCH(1, (VALUE(LEFT(fesp!$A:$A,6))=VALUE(LEFT(B13,6)))*(fesp!$C:$C=C13), 0)), "")} -> 98777 | S13: {=IFERROR(INDEX(fesp!$J:$J, MATCH(1, (VALUE(LEFT(fesp!$A:$A,6))=VALUE(LEFT(B13,6)))*(fesp!$C:$C=C13), 0)), "")} -> 1016036
A14: Manaus (AM) | B14: 1302603 | C14: 2016 | D14: {=IFERROR(INDEX(fesp!$D:$D, MATCH(1, (VALUE(LEFT(fesp!$A:$A,6))=VALUE(LEFT(B14,6)))*(fesp!$C:$C=C14), 0)), "")} -> 0 | E14: {=IFERROR(INDEX(ft_medicos_clinicos!$C:$C, MATCH(1, (VALUE(LEFT(ft_medicos_clinicos!$A:$A,6))=VALUE(LEFT(B14,6)))*(ft_medicos_clinicos!$B:$B=C14), 0)), "")} -> 686 | F14: {=IFERROR(INDEX(ft_enfermeiros!$C:$C, MATCH(1, (VALUE(LEFT(ft_enfermeiros!$A:$A,6))=VALUE(LEFT(B14,6)))*(ft_enfermeiros!$B:$B=C14), 0)), "")} -> 1451 | G14: {=IFERROR(INDEX(ft_equipes_acs!$C:$C, MATCH(1, (VALUE(LEFT(ft_equipes_acs!$A:$A,6))=VALUE(LEFT(B14,6)))*(ft_equipes_acs!$B:$B=C14), 0)), "")} | H14: {=IFERROR(INDEX(ci_leitos_internacao!$C:$C, MATCH(1, (VALUE(LEFT(ci_leitos_internacao!$A:$A,6))=VALUE(LEFT(B14,6)))*(ci_leitos_internacao!$B:$B=C14), 0)), "")} -> 3482 | I14: {=IFERROR(INDEX(ci_hospitais_internacao!$C:$C, MATCH(1, (VALUE(LEFT(ci_hospitais_internacao!$A:$A,6))=VALUE(LEFT(B14,6)))*(ci_hospitais_internacao!$B:$B=C14), 0)), "")} -> 11 | J14: {=IFERROR(INDEX(ci_pa_clinico!$C:$C, MATCH(1, (VALUE(LEFT(ci_pa_clinico!$A:$A,6))=VALUE(LEFT(B14,6)))*(ci_pa_clinico!$B:$B=C14), 0)), "")} | K14: {=IFERROR(INDEX(aps_equipes_esf!$C:$C, MATCH(1, (VALUE(LEFT(aps_equipes_esf!$A:$A,6))=VALUE(LEFT(B14,6)))*(aps_equipes_esf!$B:$B=C14), 0)), "")} -> 120 | L14: {=IFERROR(INDEX(casos!$C:$C, MATCH(1, (VALUE(LEFT(casos!$A:$A,6))=VALUE(LEFT(B14,6)))*(casos!$B:$B=C14), 0)), "")} -> 5359 | M14: {=IFERROR(INDEX(srag!$D:$D, MATCH(1, (VALUE(LEFT(srag!$A:$A,6))=VALUE(LEFT(B14,6)))*(srag!$C:$C=C14), 0)), "")} -> 132 | N14: {=IFERROR(INDEX(fesp!$E:$E, MATCH(1, (VALUE(LEFT(fesp!$A:$A,6))=VALUE(LEFT(B14,6)))*(fesp!$C:$C=C14), 0)), "")} -> 697 | O14: {=IFERROR(INDEX(fesp!$F:$F, MATCH(1, (VALUE(LEFT(fesp!$A:$A,6))=VALUE(LEFT(B14,6)))*(fesp!$C:$C=C14), 0)), "")} -> 20256 | P14: {=IFERROR(INDEX(fesp!$G:$G, MATCH(1, (VALUE(LEFT(fesp!$A:$A,6))=VALUE(LEFT(B14,6)))*(fesp!$C:$C=C14), 0)), "")} -> 15059115 | Q14: {=IFERROR(INDEX(fesp!$H:$H, MATCH(1, (VALUE(LEFT(fesp!$A:$A,6))=VALUE(LEFT(B14,6)))*(fesp!$C:$C=C14), 0)), "")} -> 495 | R14: {=IFERROR(INDEX(fesp!$I:$I, MATCH(1, (VALUE(LEFT(fesp!$A:$A,6))=VALUE(LEFT(B14,6)))*(fesp!$C:$C=C14), 0)), "")} -> 170116 | S14: {=IFERROR(INDEX(fesp!$J:$J, MATCH(1, (VALUE(LEFT(fesp!$A:$A,6))=VALUE(LEFT(B14,6)))*(fesp!$C:$C=C14), 0)), "")} -> 1138916
A15: Manaus (AM) | B15: 1302603 | C15: 2017 | D15: {=IFERROR(INDEX(fesp!$D:$D, MATCH(1, (VALUE(LEFT(fesp!$A:$A,6))=VALUE(LEFT(B15,6)))*(fesp!$C:$C=C15), 0)), "")} -> 0 | E15: {=IFERROR(INDEX(ft_medicos_clinicos!$C:$C, MATCH(1, (VALUE(LEFT(ft_medicos_clinicos!$A:$A,6))=VALUE(LEFT(B15,6)))*(ft_medicos_clinicos!$B:$B=C15), 0)), "")} -> 714 | F15: {=IFERROR(INDEX(ft_enfermeiros!$C:$C, MATCH(1, (VALUE(LEFT(ft_enfermeiros!$A:$A,6))=VALUE(LEFT(B15,6)))*(ft_enfermeiros!$B:$B=C15), 0)), "")} -> 1877 | G15: {=IFERROR(INDEX(ft_equipes_acs!$C:$C, MATCH(1, (VALUE(LEFT(ft_equipes_acs!$A:$A,6))=VALUE(LEFT(B15,6)))*(ft_equipes_acs!$B:$B=C15), 0)), "")} | H15: {=IFERROR(INDEX(ci_leitos_internacao!$C:$C, MATCH(1, (VALUE(LEFT(ci_leitos_internacao!$A:$A,6))=VALUE(LEFT(B15,6)))*(ci_leitos_internacao!$B:$B=C15), 0)), "")} -> 3453 | I15: {=IFERROR(INDEX(ci_hospitais_internacao!$C:$C, MATCH(1, (VALUE(LEFT(ci_hospitais_internacao!$A:$A,6))=VALUE(LEFT(B15,6)))*(ci_hospitais_internacao!$B:$B=C15), 0)), "")} -> 11 | J15: {=IFERROR(INDEX(ci_pa_clinico!$C:$C, MATCH(1, (VALUE(LEFT(ci_pa_clinico!$A:$A,6))=VALUE(LEFT(B15,6)))*(ci_pa_clinico!$B:$B=C15), 0)), "")} | K15: {=IFERROR(INDEX(aps_equipes_esf!$C:$C, MATCH(1, (VALUE(LEFT(aps_equipes_esf!$A:$A,6))=VALUE(LEFT(B15,6)))*(aps_equipes_esf!$B:$B=C15), 0)), "")} -> 115 | L15: {=IFERROR(INDEX(casos!$C:$C, MATCH(1, (VALUE(LEFT(casos!$A:$A,6))=VALUE(LEFT(B15,6)))*(casos!$B:$B=C15), 0)), "")} -> 2554 | M15: {=IFERROR(INDEX(srag!$D:$D, MATCH(1, (VALUE(LEFT(srag!$A:$A,6))=VALUE(LEFT(B15,6)))*(srag!$C:$C=C15), 0)), "")} -> 487 | N15: {=IFERROR(INDEX(fesp!$E:$E, MATCH(1, (VALUE(LEFT(fesp!$A:$A,6))=VALUE(LEFT(B15,6)))*(fesp!$C:$C=C15), 0)), "")} -> 551 | O15: {=IFERROR(INDEX(fesp!$F:$F, MATCH(1, (VALUE(LEFT(fesp!$A:$A,6))=VALUE(LEFT(B15,6)))*(fesp!$C:$C=C15), 0)), "")} -> 21578 | P15: {=IFERROR(INDEX(fesp!$G:$G, MATCH(1, (VALUE(LEFT(fesp!$A:$A,6))=VALUE(LEFT(B15,6)))*(fesp!$C:$C=C15), 0)), "")} -> 15386998 | Q15: {=IFERROR(INDEX(fesp!$H:$H, MATCH(1, (VALUE(LEFT(fesp!$A:$A,6))=VALUE(LEFT(B15,6)))*(fesp!$C:$C=C15), 0)), "")} -> 449 | R15: {=IFERROR(INDEX(fesp!$I:$I, MATCH(1, (VALUE(LEFT(fesp!$A:$A,6))=VALUE(LEFT(B15,6)))*(fesp!$C:$C=C15), 0)), "")} -> 140573 | S15: {=IFERROR(INDEX(fesp!$J:$J, MATCH(1, (VALUE(LEFT(fesp!$A:$A,6))=VALUE(LEFT(B15,6)))*(fesp!$C:$C=C15), 0)), "")} -> 900600
A16: Manaus (AM) | B16: 1302603 | C16: 2018 | D16: {=IFERROR(INDEX(fesp!$D:$D, MATCH(1, (VALUE(LEFT(fesp!$A:$A,6))=VALUE(LEFT(B16,6)))*(fesp!$C:$C=C16), 0)), "")} -> 0 | E16: {=IFERROR(INDEX(ft_medicos_clinicos!$C:$C, MATCH(1, (VALUE(LEFT(ft_medicos_clinicos!$A:$A,6))=VALUE(LEFT(B16,6)))*(ft_medicos_clinicos!$B:$B=C16), 0)), "")} -> 738 | F16: {=IFERROR(INDEX(ft_enfermeiros!$C:$C, MATCH(1, (VALUE(LEFT(ft_enfermeiros!$A:$A,6))=VALUE(LEFT(B16,6)))*(ft_enfermeiros!$B:$B=C16), 0)), "")} -> 2063 | G16: {=IFERROR(INDEX(ft_equipes_acs!$C:$C, MATCH(1, (VALUE(LEFT(ft_equipes_acs!$A:$A,6))=VALUE(LEFT(B16,6)))*(ft_equipes_acs!$B:$B=C16), 0)), "")} | H16: {=IFERROR(INDEX(ci_leitos_internacao!$C:$C, MATCH(1, (VALUE(LEFT(ci_leitos_internacao!$A:$A,6))=VALUE(LEFT(B16,6)))*(ci_leitos_internacao!$B:$B=C16), 0)), "")} -> 3425 | I16: {=IFERROR(INDEX(ci_hospitais_internacao!$C:$C, MATCH(1, (VALUE(LEFT(ci_hospitais_internacao!$A:$A,6))=VALUE(LEFT(B16,6)))*(ci_hospitais_internacao!$B:$B=C16), 0)), "")} -> 11 | J16: {=IFERROR(INDEX(ci_pa_clinico!$C:$C, MATCH(1, (VALUE(LEFT(ci_pa_clinico!$A:$A,6))=VALUE(LEFT(B16,6)))*(ci_pa_clinico!$B:$B=C16), 0)), "")} | K16: {=IFERROR(INDEX(aps_equipes_esf!$C:$C, MATCH(1, (VALUE(LEFT(aps_equipes_esf!$A:$A,6))=VALUE(LEFT(B16,6)))*(aps_equipes_esf!$B:$B=C16), 0)), "")} -> 124 | L16: {=IFERROR(INDEX(casos!$C:$C, MATCH(1, (VALUE(LEFT(casos!$A:$A,6))=VALUE(LEFT(B16,6)))*(casos!$B:$B=C16), 0)), "")} -> 1303 | M16: {=IFERROR(INDEX(srag!$D:$D, MATCH(1, (VALUE(LEFT(srag!$A:$A,6))=VALUE(LEFT(B16,6)))*(srag!$C:$C=C16), 0)), "")} -> 230 | N16: {=IFERROR(INDEX(fesp!$E:$E, MATCH(1, (VALUE(LEFT(fesp!$A:$A,6))=VALUE(LEFT(B16,6)))*(fesp!$C:$C=C16), 0)), "")} -> 702 | O16: {=IFERROR(INDEX(fesp!$F:$F, MATCH(1, (VALUE(LEFT(fesp!$A:$A,6))=VALUE(LEFT(B16,6)))*(fesp!$C:$C=C16), 0)), "")} -> 21114 | P16: {=IFERROR(INDEX(fesp!$G:$G, MATCH(1, (VALUE(LEFT(fesp!$A:$A,6))=VALUE(LEFT(B16,6)))*(fesp!$C:$C=C16), 0)), "")} -> 14543338 | Q16: {=IFERROR(INDEX(fesp!$H:$H, MATCH(1, (VALUE(LEFT(fesp!$A:$A,6))=VALUE(LEFT(B16,6)))*(fesp!$C:$C=C16), 0)), "")} -> 399 | R16: {=IFERROR(INDEX(fesp!$I:$I, MATCH(1, (VALUE(LEFT(fesp!$A:$A,6))=VALUE(LEFT(B16,6)))*(fesp!$C:$C=C16), 0)), "")} -> 69709 | S16: {=IFERROR(INDEX(fesp!$J:$J, MATCH(1, (VALUE(LEFT(fesp!$A:$A,6))=VALUE(LEFT(B16,6)))*(fesp!$C:$C=C16), 0)), "")} -> 760578
A17: Manaus (AM) | B17: 1302603 | C17: 2019 | D17: {=IFERROR(INDEX(fesp!$D:$D, MATCH(1, (VALUE(LEFT(fesp!$A:$A,6))=VALUE(LEFT(B17,6)))*(fesp!$C:$C=C17), 0)), "")} -> 0 | E17: {=IFERROR(INDEX(ft_medicos_clinicos!$C:$C, MATCH(1, (VALUE(LEFT(ft_medicos_clinicos!$A:$A,6))=VALUE(LEFT(B17,6)))*(ft_medicos_clinicos!$B:$B=C17), 0)), "")} -> 903 | F17: {=IFERROR(INDEX(ft_enfermeiros!$C:$C, MATCH(1, (VALUE(LEFT(ft_enfermeiros!$A:$A,6))=VALUE(LEFT(B17,6)))*(ft_enfermeiros!$B:$B=C17), 0)), "")} -> 2041 | G17: {=IFERROR(INDEX(ft_equipes_acs!$C:$C, MATCH(1, (VALUE(LEFT(ft_equipes_acs!$A:$A,6))=VALUE(LEFT(B17,6)))*(ft_equipes_acs!$B:$B=C17), 0)), "")} | H17: {=IFERROR(INDEX(ci_leitos_internacao!$C:$C, MATCH(1, (VALUE(LEFT(ci_leitos_internacao!$A:$A,6))=VALUE(LEFT(B17,6)))*(ci_leitos_internacao!$B:$B=C17), 0)), "")} -> 3338 | I17: {=IFERROR(INDEX(ci_hospitais_internacao!$C:$C, MATCH(1, (VALUE(LEFT(ci_hospitais_internacao!$A:$A,6))=VALUE(LEFT(B17,6)))*(ci_hospitais_internacao!$B:$B=C17), 0)), "")} -> 11 | J17: {=IFERROR(INDEX(ci_pa_clinico!$C:$C, MATCH(1, (VALUE(LEFT(ci_pa_clinico!$A:$A,6))=VALUE(LEFT(B17,6)))*(ci_pa_clinico!$B:$B=C17), 0)), "")} | K17: {=IFERROR(INDEX(aps_equipes_esf!$C:$C, MATCH(1, (VALUE(LEFT(aps_equipes_esf!$A:$A,6))=VALUE(LEFT(B17,6)))*(aps_equipes_esf!$B:$B=C17), 0)), "")} -> 127 | L17: {=IFERROR(INDEX(casos!$C:$C, MATCH(1, (VALUE(LEFT(casos!$A:$A,6))=VALUE(LEFT(B17,6)))*(casos!$B:$B=C17), 0)), "")} -> 477 | M17: {=IFERROR(INDEX(srag!$D:$D, MATCH(1, (VALUE(LEFT(srag!$A:$A,6))=VALUE(LEFT(B17,6)))*(srag!$C:$C=C17), 0)), "")} -> 1608 | N17: {=IFERROR(INDEX(fesp!$E:$E, MATCH(1, (VALUE(LEFT(fesp!$A:$A,6))=VALUE(LEFT(B17,6)))*(fesp!$C:$C=C17), 0)), "")} -> 522 | O17: {=IFERROR(INDEX(fesp!$F:$F, MATCH(1, (VALUE(LEFT(fesp!$A:$A,6))=VALUE(LEFT(B17,6)))*(fesp!$C:$C=C17), 0)), "")} -> 20016 | P17: {=IFERROR(INDEX(fesp!$G:$G, MATCH(1, (VALUE(LEFT(fesp!$A:$A,6))=VALUE(LEFT(B17,6)))*(fesp!$C:$C=C17), 0)), "")} -> 15110985 | Q17: {=IFERROR(INDEX(fesp!$H:$H, MATCH(1, (VALUE(LEFT(fesp!$A:$A,6))=VALUE(LEFT(B17,6)))*(fesp!$C:$C=C17), 0)), "")} -> 481 | R17: {=IFERROR(INDEX(fesp!$I:$I, MATCH(1, (VALUE(LEFT(fesp!$A:$A,6))=VALUE(LEFT(B17,6)))*(fesp!$C:$C=C17), 0)), "")} -> 46200 | S17: {=IFERROR(INDEX(fesp!$J:$J, MATCH(1, (VALUE(LEFT(fesp!$A:$A,6))=VALUE(LEFT(B17,6)))*(fesp!$C:$C=C17), 0)), "")} -> 356420
A18: Manaus (AM) | B18: 1302603 | C18: 2020 | D18: {=IFERROR(INDEX(fesp!$D:$D, MATCH(1, (VALUE(LEFT(fesp!$A:$A,6))=VALUE(LEFT(B18,6)))*(fesp!$C:$C=C18), 0)), "")} -> 0 | E18: {=IFERROR(INDEX(ft_medicos_clinicos!$C:$C, MATCH(1, (VALUE(LEFT(ft_medicos_clinicos!$A:$A,6))=VALUE(LEFT(B18,6)))*(ft_medicos_clinicos!$B:$B=C18), 0)), "")} -> 980 | F18: {=IFERROR(INDEX(ft_enfermeiros!$C:$C, MATCH(1, (VALUE(LEFT(ft_enfermeiros!$A:$A,6))=VALUE(LEFT(B18,6)))*(ft_enfermeiros!$B:$B=C18), 0)), "")} -> 2679 | G18: {=IFERROR(INDEX(ft_equipes_acs!$C:$C, MATCH(1, (VALUE(LEFT(ft_equipes_acs!$A:$A,6))=VALUE(LEFT(B18,6)))*(ft_equipes_acs!$B:$B=C18), 0)), "")} | H18: {=IFERROR(INDEX(ci_leitos_internacao!$C:$C, MATCH(1, (VALUE(LEFT(ci_leitos_internacao!$A:$A,6))=VALUE(LEFT(B18,6)))*(ci_leitos_internacao!$B:$B=C18), 0)), "")} -> 3389 | I18: {=IFERROR(INDEX(ci_hospitais_internacao!$C:$C, MATCH(1, (VALUE(LEFT(ci_hospitais_internacao!$A:$A,6))=VALUE(LEFT(B18,6)))*(ci_hospitais_internacao!$B:$B=C18), 0)), "")} -> 11 | J18: {=IFERROR(INDEX(ci_pa_clinico!$C:$C, MATCH(1, (VALUE(LEFT(ci_pa_clinico!$A:$A,6))=VALUE(LEFT(B18,6)))*(ci_pa_clinico!$B:$B=C18), 0)), "")} | K18: {=IFERROR(INDEX(aps_equipes_esf!$C:$C, MATCH(1, (VALUE(LEFT(aps_equipes_esf!$A:$A,6))=VALUE(LEFT(B18,6)))*(aps_equipes_esf!$B:$B=C18), 0)), "")} -> - | L18: {=IFERROR(INDEX(casos!$C:$C, MATCH(1, (VALUE(LEFT(casos!$A:$A,6))=VALUE(LEFT(B18,6)))*(casos!$B:$B=C18), 0)), "")} -> 959 | M18: {=IFERROR(INDEX(srag!$D:$D, MATCH(1, (VALUE(LEFT(srag!$A:$A,6))=VALUE(LEFT(B18,6)))*(srag!$C:$C=C18), 0)), "")} -> 15281 | N18: {=IFERROR(INDEX(fesp!$E:$E, MATCH(1, (VALUE(LEFT(fesp!$A:$A,6))=VALUE(LEFT(B18,6)))*(fesp!$C:$C=C18), 0)), "")} -> 545 | O18: {=IFERROR(INDEX(fesp!$F:$F, MATCH(1, (VALUE(LEFT(fesp!$A:$A,6))=VALUE(LEFT(B18,6)))*(fesp!$C:$C=C18), 0)), "")} -> 13304 | P18: {=IFERROR(INDEX(fesp!$G:$G, MATCH(1, (VALUE(LEFT(fesp!$A:$A,6))=VALUE(LEFT(B18,6)))*(fesp!$C:$C=C18), 0)), "")} -> 11358728 | Q18: {=IFERROR(INDEX(fesp!$H:$H, MATCH(1, (VALUE(LEFT(fesp!$A:$A,6))=VALUE(LEFT(B18,6)))*(fesp!$C:$C=C18), 0)), "")} -> 501 | R18: {=IFERROR(INDEX(fesp!$I:$I, MATCH(1, (VALUE(LEFT(fesp!$A:$A,6))=VALUE(LEFT(B18,6)))*(fesp!$C:$C=C18), 0)), "")} -> 6335 | S18: {=IFERROR(INDEX(fesp!$J:$J, MATCH(1, (VALUE(LEFT(fesp!$A:$A,6))=VALUE(LEFT(B18,6)))*(fesp!$C:$C=C18), 0)), "")} -> 56062
A19: Manaus (AM) | B19: 1302603 | C19: 2021 | D19: {=IFERROR(INDEX(fesp!$D:$D, MATCH(1, (VALUE(LEFT(fesp!$A:$A,6))=VALUE(LEFT(B19,6)))*(fesp!$C:$C=C19), 0)), "")} -> 0 | E19: {=IFERROR(INDEX(ft_medicos_clinicos!$C:$C, MATCH(1, (VALUE(LEFT(ft_medicos_clinicos!$A:$A,6))=VALUE(LEFT(B19,6)))*(ft_medicos_clinicos!$B:$B=C19), 0)), "")} -> 1146 | F19: {=IFERROR(INDEX(ft_enfermeiros!$C:$C, MATCH(1, (VALUE(LEFT(ft_enfermeiros!$A:$A,6))=VALUE(LEFT(B19,6)))*(ft_enfermeiros!$B:$B=C19), 0)), "")} -> 3094 | G19: {=IFERROR(INDEX(ft_equipes_acs!$C:$C, MATCH(1, (VALUE(LEFT(ft_equipes_acs!$A:$A,6))=VALUE(LEFT(B19,6)))*(ft_equipes_acs!$B:$B=C19), 0)), "")} | H19: {=IFERROR(INDEX(ci_leitos_internacao!$C:$C, MATCH(1, (VALUE(LEFT(ci_leitos_internacao!$A:$A,6))=VALUE(LEFT(B19,6)))*(ci_leitos_internacao!$B:$B=C19), 0)), "")} -> 3607 | I19: {=IFERROR(INDEX(ci_hospitais_internacao!$C:$C, MATCH(1, (VALUE(LEFT(ci_hospitais_internacao!$A:$A,6))=VALUE(LEFT(B19,6)))*(ci_hospitais_internacao!$B:$B=C19), 0)), "")} -> 11 | J19: {=IFERROR(INDEX(ci_pa_clinico!$C:$C, MATCH(1, (VALUE(LEFT(ci_pa_clinico!$A:$A,6))=VALUE(LEFT(B19,6)))*(ci_pa_clinico!$B:$B=C19), 0)), "")} | K19: {=IFERROR(INDEX(aps_equipes_esf!$C:$C, MATCH(1, (VALUE(LEFT(aps_equipes_esf!$A:$A,6))=VALUE(LEFT(B19,6)))*(aps_equipes_esf!$B:$B=C19), 0)), "")} -> - | L19: {=IFERROR(INDEX(casos!$C:$C, MATCH(1, (VALUE(LEFT(casos!$A:$A,6))=VALUE(LEFT(B19,6)))*(casos!$B:$B=C19), 0)), "")} -> 4016 | M19: {=IFERROR(INDEX(srag!$D:$D, MATCH(1, (VALUE(LEFT(srag!$A:$A,6))=VALUE(LEFT(B19,6)))*(srag!$C:$C=C19), 0)), "")} -> 18437 | N19: {=IFERROR(INDEX(fesp!$E:$E, MATCH(1, (VALUE(LEFT(fesp!$A:$A,6))=VALUE(LEFT(B19,6)))*(fesp!$C:$C=C19), 0)), "")} -> 903 | O19: {=IFERROR(INDEX(fesp!$F:$F, MATCH(1, (VALUE(LEFT(fesp!$A:$A,6))=VALUE(LEFT(B19,6)))*(fesp!$C:$C=C19), 0)), "")} -> 12771 | P19: {=IFERROR(INDEX(fesp!$G:$G, MATCH(1, (VALUE(LEFT(fesp!$A:$A,6))=VALUE(LEFT(B19,6)))*(fesp!$C:$C=C19), 0)), "")} -> 13395881 | Q19: {=IFERROR(INDEX(fesp!$H:$H, MATCH(1, (VALUE(LEFT(fesp!$A:$A,6))=VALUE(LEFT(B19,6)))*(fesp!$C:$C=C19), 0)), "")} -> 458 | R19: {=IFERROR(INDEX(fesp!$I:$I, MATCH(1, (VALUE(LEFT(fesp!$A:$A,6))=VALUE(LEFT(B19,6)))*(fesp!$C:$C=C19), 0)), "")} -> 1964 | S19: {=IFERROR(INDEX(fesp!$J:$J, MATCH(1, (VALUE(LEFT(fesp!$A:$A,6))=VALUE(LEFT(B19,6)))*(fesp!$C:$C=C19), 0)), "")} -> 17747
A20: Manaus (AM) | B20: 1302603 | C20: 2022 | D20: {=IFERROR(INDEX(fesp!$D:$D, MATCH(1, (VALUE(LEFT(fesp!$A:$A,6))=VALUE(LEFT(B20,6)))*(fesp!$C:$C=C20), 0)), "")} -> 2063689 | E20: {=IFERROR(INDEX(ft_medicos_clinicos!$C:$C, MATCH(1, (VALUE(LEFT(ft_medicos_clinicos!$A:$A,6))=VALUE(LEFT(B20,6)))*(ft_medicos_clinicos!$B:$B=C20), 0)), "")} -> 1270 | F20: {=IFERROR(INDEX(ft_enfermeiros!$C:$C, MATCH(1, (VALUE(LEFT(ft_enfermeiros!$A:$A,6))=VALUE(LEFT(B20,6)))*(ft_enfermeiros!$B:$B=C20), 0)), "")} -> 3232 | G20: {=IFERROR(INDEX(ft_equipes_acs!$C:$C, MATCH(1, (VALUE(LEFT(ft_equipes_acs!$A:$A,6))=VALUE(LEFT(B20,6)))*(ft_equipes_acs!$B:$B=C20), 0)), "")} | H20: {=IFERROR(INDEX(ci_leitos_internacao!$C:$C, MATCH(1, (VALUE(LEFT(ci_leitos_internacao!$A:$A,6))=VALUE(LEFT(B20,6)))*(ci_leitos_internacao!$B:$B=C20), 0)), "")} -> 3648 | I20: {=IFERROR(INDEX(ci_hospitais_internacao!$C:$C, MATCH(1, (VALUE(LEFT(ci_hospitais_internacao!$A:$A,6))=VALUE(LEFT(B20,6)))*(ci_hospitais_internacao!$B:$B=C20), 0)), "")} -> 12 | J20: {=IFERROR(INDEX(ci_pa_clinico!$C:$C, MATCH(1, (VALUE(LEFT(ci_pa_clinico!$A:$A,6))=VALUE(LEFT(B20,6)))*(ci_pa_clinico!$B:$B=C20), 0)), "")} | K20: {=IFERROR(INDEX(aps_equipes_esf!$C:$C, MATCH(1, (VALUE(LEFT(aps_equipes_esf!$A:$A,6))=VALUE(LEFT(B20,6)))*(aps_equipes_esf!$B:$B=C20), 0)), "")} -> - | L20: {=IFERROR(INDEX(casos!$C:$C, MATCH(1, (VALUE(LEFT(casos!$A:$A,6))=VALUE(LEFT(B20,6)))*(casos!$B:$B=C20), 0)), "")} -> 1197 | M20: {=IFERROR(INDEX(srag!$D:$D, MATCH(1, (VALUE(LEFT(srag!$A:$A,6))=VALUE(LEFT(B20,6)))*(srag!$C:$C=C20), 0)), "")} -> 4170 | N20: {=IFERROR(INDEX(fesp!$E:$E, MATCH(1, (VALUE(LEFT(fesp!$A:$A,6))=VALUE(LEFT(B20,6)))*(fesp!$C:$C=C20), 0)), "")} -> 952 | O20: {=IFERROR(INDEX(fesp!$F:$F, MATCH(1, (VALUE(LEFT(fesp!$A:$A,6))=VALUE(LEFT(B20,6)))*(fesp!$C:$C=C20), 0)), "")} -> 14630 | P20: {=IFERROR(INDEX(fesp!$G:$G, MATCH(1, (VALUE(LEFT(fesp!$A:$A,6))=VALUE(LEFT(B20,6)))*(fesp!$C:$C=C20), 0)), "")} -> 15598169 | Q20: {=IFERROR(INDEX(fesp!$H:$H, MATCH(1, (VALUE(LEFT(fesp!$A:$A,6))=VALUE(LEFT(B20,6)))*(fesp!$C:$C=C20), 0)), "")} -> 416 | R20: {=IFERROR(INDEX(fesp!$I:$I, MATCH(1, (VALUE(LEFT(fesp!$A:$A,6))=VALUE(LEFT(B20,6)))*(fesp!$C:$C=C20), 0)), "")} -> 845 | S20: {=IFERROR(INDEX(fesp!$J:$J, MATCH(1, (VALUE(LEFT(fesp!$A:$A,6))=VALUE(LEFT(B20,6)))*(fesp!$C:$C=C20), 0)), "")} -> 10301
A21: Manaus (AM) | B21: 1302603 | C21: 2023 | D21: {=IFERROR(INDEX(fesp!$D:$D, MATCH(1, (VALUE(LEFT(fesp!$A:$A,6))=VALUE(LEFT(B21,6)))*(fesp!$C:$C=C21), 0)), "")} -> 0 | E21: {=IFERROR(INDEX(ft_medicos_clinicos!$C:$C, MATCH(1, (VALUE(LEFT(ft_medicos_clinicos!$A:$A,6))=VALUE(LEFT(B21,6)))*(ft_medicos_clinicos!$B:$B=C21), 0)), "")} -> 1313 | F21: {=IFERROR(INDEX(ft_enfermeiros!$C:$C, MATCH(1, (VALUE(LEFT(ft_enfermeiros!$A:$A,6))=VALUE(LEFT(B21,6)))*(ft_enfermeiros!$B:$B=C21), 0)), "")} -> 3946 | G21: {=IFERROR(INDEX(ft_equipes_acs!$C:$C, MATCH(1, (VALUE(LEFT(ft_equipes_acs!$A:$A,6))=VALUE(LEFT(B21,6)))*(ft_equipes_acs!$B:$B=C21), 0)), "")} | H21: {=IFERROR(INDEX(ci_leitos_internacao!$C:$C, MATCH(1, (VALUE(LEFT(ci_leitos_internacao!$A:$A,6))=VALUE(LEFT(B21,6)))*(ci_leitos_internacao!$B:$B=C21), 0)), "")} -> 3715 | I21: {=IFERROR(INDEX(ci_hospitais_internacao!$C:$C, MATCH(1, (VALUE(LEFT(ci_hospitais_internacao!$A:$A,6))=VALUE(LEFT(B21,6)))*(ci_hospitais_internacao!$B:$B=C21), 0)), "")} -> 12 | J21: {=IFERROR(INDEX(ci_pa_clinico!$C:$C, MATCH(1, (VALUE(LEFT(ci_pa_clinico!$A:$A,6))=VALUE(LEFT(B21,6)))*(ci_pa_clinico!$B:$B=C21), 0)), "")} | K21: {=IFERROR(INDEX(aps_equipes_esf!$C:$C, MATCH(1, (VALUE(LEFT(aps_equipes_esf!$A:$A,6))=VALUE(LEFT(B21,6)))*(aps_equipes_esf!$B:$B=C21), 0)), "")} -> - | L21: {=IFERROR(INDEX(casos!$C:$C, MATCH(1, (VALUE(LEFT(casos!$A:$A,6))=VALUE(LEFT(B21,6)))*(casos!$B:$B=C21), 0)), "")} -> 1172 | M21: {=IFERROR(INDEX(srag!$D:$D, MATCH(1, (VALUE(LEFT(srag!$A:$A,6))=VALUE(LEFT(B21,6)))*(srag!$C:$C=C21), 0)), "")} -> 2409 | N21: {=IFERROR(INDEX(fesp!$E:$E, MATCH(1, (VALUE(LEFT(fesp!$A:$A,6))=VALUE(LEFT(B21,6)))*(fesp!$C:$C=C21), 0)), "")} -> 972 | O21: {=IFERROR(INDEX(fesp!$F:$F, MATCH(1, (VALUE(LEFT(fesp!$A:$A,6))=VALUE(LEFT(B21,6)))*(fesp!$C:$C=C21), 0)), "")} -> 22494 | P21: {=IFERROR(INDEX(fesp!$G:$G, MATCH(1, (VALUE(LEFT(fesp!$A:$A,6))=VALUE(LEFT(B21,6)))*(fesp!$C:$C=C21), 0)), "")} -> 16240672 | Q21: {=IFERROR(INDEX(fesp!$H:$H, MATCH(1, (VALUE(LEFT(fesp!$A:$A,6))=VALUE(LEFT(B21,6)))*(fesp!$C:$C=C21), 0)), "")} -> 415 | R21: {=IFERROR(INDEX(fesp!$I:$I, MATCH(1, (VALUE(LEFT(fesp!$A:$A,6))=VALUE(LEFT(B21,6)))*(fesp!$C:$C=C21), 0)), "")} -> 787 | S21: {=IFERROR(INDEX(fesp!$J:$J, MATCH(1, (VALUE(LEFT(fesp!$A:$A,6))=VALUE(LEFT(B21,6)))*(fesp!$C:$C=C21), 0)), "")} -> 20724
A22: Manaus (AM) | B22: 1302603 | C22: 2024 | D22: {=IFERROR(INDEX(fesp!$D:$D, MATCH(1, (VALUE(LEFT(fesp!$A:$A,6))=VALUE(LEFT(B22,6)))*(fesp!$C:$C=C22), 0)), "")} -> 0 | E22: {=IFERROR(INDEX(ft_medicos_clinicos!$C:$C, MATCH(1, (VALUE(LEFT(ft_medicos_clinicos!$A:$A,6))=VALUE(LEFT(B22,6)))*(ft_medicos_clinicos!$B:$B=C22), 0)), "")} -> 1423 | F22: {=IFERROR(INDEX(ft_enfermeiros!$C:$C, MATCH(1, (VALUE(LEFT(ft_enfermeiros!$A:$A,6))=VALUE(LEFT(B22,6)))*(ft_enfermeiros!$B:$B=C22), 0)), "")} -> 3716 | G22: {=IFERROR(INDEX(ft_equipes_acs!$C:$C, MATCH(1, (VALUE(LEFT(ft_equipes_acs!$A:$A,6))=VALUE(LEFT(B22,6)))*(ft_equipes_acs!$B:$B=C22), 0)), "")} | H22: {=IFERROR(INDEX(ci_leitos_internacao!$C:$C, MATCH(1, (VALUE(LEFT(ci_leitos_internacao!$A:$A,6))=VALUE(LEFT(B22,6)))*(ci_leitos_internacao!$B:$B=C22), 0)), "")} -> 3959 | I22: {=IFERROR(INDEX(ci_hospitais_internacao!$C:$C, MATCH(1, (VALUE(LEFT(ci_hospitais_internacao!$A:$A,6))=VALUE(LEFT(B22,6)))*(ci_hospitais_internacao!$B:$B=C22), 0)), "")} -> 13 | J22: {=IFERROR(INDEX(ci_pa_clinico!$C:$C, MATCH(1, (VALUE(LEFT(ci_pa_clinico!$A:$A,6))=VALUE(LEFT(B22,6)))*(ci_pa_clinico!$B:$B=C22), 0)), "")} | K22: {=IFERROR(INDEX(aps_equipes_esf!$C:$C, MATCH(1, (VALUE(LEFT(aps_equipes_esf!$A:$A,6))=VALUE(LEFT(B22,6)))*(aps_equipes_esf!$B:$B=C22), 0)), "")} -> - | L22: {=IFERROR(INDEX(casos!$C:$C, MATCH(1, (VALUE(LEFT(casos!$A:$A,6))=VALUE(LEFT(B22,6)))*(casos!$B:$B=C22), 0)), "")} -> 2606 | M22: {=IFERROR(INDEX(srag!$D:$D, MATCH(1, (VALUE(LEFT(srag!$A:$A,6))=VALUE(LEFT(B22,6)))*(srag!$C:$C=C22), 0)), "")} -> 2313 | N22: {=IFERROR(INDEX(fesp!$E:$E, MATCH(1, (VALUE(LEFT(fesp!$A:$A,6))=VALUE(LEFT(B22,6)))*(fesp!$C:$C=C22), 0)), "")} -> 792 | O22: {=IFERROR(INDEX(fesp!$F:$F, MATCH(1, (VALUE(LEFT(fesp!$A:$A,6))=VALUE(LEFT(B22,6)))*(fesp!$C:$C=C22), 0)), "")} -> 26000 | P22: {=IFERROR(INDEX(fesp!$G:$G, MATCH(1, (VALUE(LEFT(fesp!$A:$A,6))=VALUE(LEFT(B22,6)))*(fesp!$C:$C=C22), 0)), "")} -> 17718719 | Q22: {=IFERROR(INDEX(fesp!$H:$H, MATCH(1, (VALUE(LEFT(fesp!$A:$A,6))=VALUE(LEFT(B22,6)))*(fesp!$C:$C=C22), 0)), "")} -> 387 | R22: {=IFERROR(INDEX(fesp!$I:$I, MATCH(1, (VALUE(LEFT(fesp!$A:$A,6))=VALUE(LEFT(B22,6)))*(fesp!$C:$C=C22), 0)), "")} -> 3058 | S22: {=IFERROR(INDEX(fesp!$J:$J, MATCH(1, (VALUE(LEFT(fesp!$A:$A,6))=VALUE(LEFT(B22,6)))*(fesp!$C:$C=C22), 0)), "")} -> 2573497
A23: Manaus (AM) | B23: 1302603 | C23: 2025 | D23: {=IFERROR(INDEX(fesp!$D:$D, MATCH(1, (VALUE(LEFT(fesp!$A:$A,6))=VALUE(LEFT(B23,6)))*(fesp!$C:$C=C23), 0)), "")} -> 0 | E23: {=IFERROR(INDEX(ft_medicos_clinicos!$C:$C, MATCH(1, (VALUE(LEFT(ft_medicos_clinicos!$A:$A,6))=VALUE(LEFT(B23,6)))*(ft_medicos_clinicos!$B:$B=C23), 0)), "")} -> 1843 | F23: {=IFERROR(INDEX(ft_enfermeiros!$C:$C, MATCH(1, (VALUE(LEFT(ft_enfermeiros!$A:$A,6))=VALUE(LEFT(B23,6)))*(ft_enfermeiros!$B:$B=C23), 0)), "")} -> 3879 | G23: {=IFERROR(INDEX(ft_equipes_acs!$C:$C, MATCH(1, (VALUE(LEFT(ft_equipes_acs!$A:$A,6))=VALUE(LEFT(B23,6)))*(ft_equipes_acs!$B:$B=C23), 0)), "")} | H23: {=IFERROR(INDEX(ci_leitos_internacao!$C:$C, MATCH(1, (VALUE(LEFT(ci_leitos_internacao!$A:$A,6))=VALUE(LEFT(B23,6)))*(ci_leitos_internacao!$B:$B=C23), 0)), "")} -> 4095 | I23: {=IFERROR(INDEX(ci_hospitais_internacao!$C:$C, MATCH(1, (VALUE(LEFT(ci_hospitais_internacao!$A:$A,6))=VALUE(LEFT(B23,6)))*(ci_hospitais_internacao!$B:$B=C23), 0)), "")} -> 12 | J23: {=IFERROR(INDEX(ci_pa_clinico!$C:$C, MATCH(1, (VALUE(LEFT(ci_pa_clinico!$A:$A,6))=VALUE(LEFT(B23,6)))*(ci_pa_clinico!$B:$B=C23), 0)), "")} | K23: {=IFERROR(INDEX(aps_equipes_esf!$C:$C, MATCH(1, (VALUE(LEFT(aps_equipes_esf!$A:$A,6))=VALUE(LEFT(B23,6)))*(aps_equipes_esf!$B:$B=C23), 0)), "")} -> - | L23: {=IFERROR(INDEX(casos!$C:$C, MATCH(1, (VALUE(LEFT(casos!$A:$A,6))=VALUE(LEFT(B23,6)))*(casos!$B:$B=C23), 0)), "")} -> 1272 | M23: {=IFERROR(INDEX(srag!$D:$D, MATCH(1, (VALUE(LEFT(srag!$A:$A,6))=VALUE(LEFT(B23,6)))*(srag!$C:$C=C23), 0)), "")} -> 2714 | N23: {=IFERROR(INDEX(fesp!$E:$E, MATCH(1, (VALUE(LEFT(fesp!$A:$A,6))=VALUE(LEFT(B23,6)))*(fesp!$C:$C=C23), 0)), "")} -> 571 | O23: {=IFERROR(INDEX(fesp!$F:$F, MATCH(1, (VALUE(LEFT(fesp!$A:$A,6))=VALUE(LEFT(B23,6)))*(fesp!$C:$C=C23), 0)), "")} -> 22385 | P23: {=IFERROR(INDEX(fesp!$G:$G, MATCH(1, (VALUE(LEFT(fesp!$A:$A,6))=VALUE(LEFT(B23,6)))*(fesp!$C:$C=C23), 0)), "")} -> 11389691 | Q23: {=IFERROR(INDEX(fesp!$H:$H, MATCH(1, (VALUE(LEFT(fesp!$A:$A,6))=VALUE(LEFT(B23,6)))*(fesp!$C:$C=C23), 0)), "")} -> 184 | R23: {=IFERROR(INDEX(fesp!$I:$I, MATCH(1, (VALUE(LEFT(fesp!$A:$A,6))=VALUE(LEFT(B23,6)))*(fesp!$C:$C=C23), 0)), "")} -> 2305 | S23: {=IFERROR(INDEX(fesp!$J:$J, MATCH(1, (VALUE(LEFT(fesp!$A:$A,6))=VALUE(LEFT(B23,6)))*(fesp!$C:$C=C23), 0)), "")} -> 50526
A24: Boa Vista (RR) | B24: 1400100 | C24: 2015 | D24: {=IFERROR(INDEX(fesp!$D:$D, MATCH(1, (VALUE(LEFT(fesp!$A:$A,6))=VALUE(LEFT(B24,6)))*(fesp!$C:$C=C24), 0)), "")} -> 320714 | E24: {=IFERROR(INDEX(ft_medicos_clinicos!$C:$C, MATCH(1, (VALUE(LEFT(ft_medicos_clinicos!$A:$A,6))=VALUE(LEFT(B24,6)))*(ft_medicos_clinicos!$B:$B=C24), 0)), "")} -> 211 | F24: {=IFERROR(INDEX(ft_enfermeiros!$C:$C, MATCH(1, (VALUE(LEFT(ft_enfermeiros!$A:$A,6))=VALUE(LEFT(B24,6)))*(ft_enfermeiros!$B:$B=C24), 0)), "")} -> 362 | G24: {=IFERROR(INDEX(ft_equipes_acs!$C:$C, MATCH(1, (VALUE(LEFT(ft_equipes_acs!$A:$A,6))=VALUE(LEFT(B24,6)))*(ft_equipes_acs!$B:$B=C24), 0)), "")} | H24: {=IFERROR(INDEX(ci_leitos_internacao!$C:$C, MATCH(1, (VALUE(LEFT(ci_leitos_internacao!$A:$A,6))=VALUE(LEFT(B24,6)))*(ci_leitos_internacao!$B:$B=C24), 0)), "")} -> 689 | I24: {=IFERROR(INDEX(ci_hospitais_internacao!$C:$C, MATCH(1, (VALUE(LEFT(ci_hospitais_internacao!$A:$A,6))=VALUE(LEFT(B24,6)))*(ci_hospitais_internacao!$B:$B=C24), 0)), "")} -> 2 | J24: {=IFERROR(INDEX(ci_pa_clinico!$C:$C, MATCH(1, (VALUE(LEFT(ci_pa_clinico!$A:$A,6))=VALUE(LEFT(B24,6)))*(ci_pa_clinico!$B:$B=C24), 0)), "")} -> - | K24: {=IFERROR(INDEX(aps_equipes_esf!$C:$C, MATCH(1, (VALUE(LEFT(aps_equipes_esf!$A:$A,6))=VALUE(LEFT(B24,6)))*(aps_equipes_esf!$B:$B=C24), 0)), "")} -> 54 | L24: {=IFERROR(INDEX(casos!$C:$C, MATCH(1, (VALUE(LEFT(casos!$A:$A,6))=VALUE(LEFT(B24,6)))*(casos!$B:$B=C24), 0)), "")} -> 439 | M24: {=IFERROR(INDEX(srag!$D:$D, MATCH(1, (VALUE(LEFT(srag!$A:$A,6))=VALUE(LEFT(B24,6)))*(srag!$C:$C=C24), 0)), "")} -> 4 | N24: {=IFERROR(INDEX(fesp!$E:$E, MATCH(1, (VALUE(LEFT(fesp!$A:$A,6))=VALUE(LEFT(B24,6)))*(fesp!$C:$C=C24), 0)), "")} -> 466 | O24: {=IFERROR(INDEX(fesp!$F:$F, MATCH(1, (VALUE(LEFT(fesp!$A:$A,6))=VALUE(LEFT(B24,6)))*(fesp!$C:$C=C24), 0)), "")} -> 3472 | P24: {=IFERROR(INDEX(fesp!$G:$G, MATCH(1, (VALUE(LEFT(fesp!$A:$A,6))=VALUE(LEFT(B24,6)))*(fesp!$C:$C=C24), 0)), "")} -> 2275887 | Q24: {=IFERROR(INDEX(fesp!$H:$H, MATCH(1, (VALUE(LEFT(fesp!$A:$A,6))=VALUE(LEFT(B24,6)))*(fesp!$C:$C=C24), 0)), "")} -> 75 | R24: {=IFERROR(INDEX(fesp!$I:$I, MATCH(1, (VALUE(LEFT(fesp!$A:$A,6))=VALUE(LEFT(B24,6)))*(fesp!$C:$C=C24), 0)), "")} -> 121076 | S24: {=IFERROR(INDEX(fesp!$J:$J, MATCH(1, (VALUE(LEFT(fesp!$A:$A,6))=VALUE(LEFT(B24,6)))*(fesp!$C:$C=C24), 0)), "")} -> 290380
A25: Boa Vista (RR) | B25: 1400100 | C25: 2016 | D25: {=IFERROR(INDEX(fesp!$D:$D, MATCH(1, (VALUE(LEFT(fesp!$A:$A,6))=VALUE(LEFT(B25,6)))*(fesp!$C:$C=C25), 0)), "")} -> 0 | E25: {=IFERROR(INDEX(ft_medicos_clinicos!$C:$C, MATCH(1, (VALUE(LEFT(ft_medicos_clinicos!$A:$A,6))=VALUE(LEFT(B25,6)))*(ft_medicos_clinicos!$B:$B=C25), 0)), "")} -> 228 | F25: {=IFERROR(INDEX(ft_enfermeiros!$C:$C, MATCH(1, (VALUE(LEFT(ft_enfermeiros!$A:$A,6))=VALUE(LEFT(B25,6)))*(ft_enfermeiros!$B:$B=C25), 0)), "")} -> 357 | G25: {=IFERROR(INDEX(ft_equipes_acs!$C:$C, MATCH(1, (VALUE(LEFT(ft_equipes_acs!$A:$A,6))=VALUE(LEFT(B25,6)))*(ft_equipes_acs!$B:$B=C25), 0)), "")} | H25: {=IFERROR(INDEX(ci_leitos_internacao!$C:$C, MATCH(1, (VALUE(LEFT(ci_leitos_internacao!$A:$A,6))=VALUE(LEFT(B25,6)))*(ci_leitos_internacao!$B:$B=C25), 0)), "")} -> 705 | I25: {=IFERROR(INDEX(ci_hospitais_internacao!$C:$C, MATCH(1, (VALUE(LEFT(ci_hospitais_internacao!$A:$A,6))=VALUE(LEFT(B25,6)))*(ci_hospitais_internacao!$B:$B=C25), 0)), "")} -> 2 | J25: {=IFERROR(INDEX(ci_pa_clinico!$C:$C, MATCH(1, (VALUE(LEFT(ci_pa_clinico!$A:$A,6))=VALUE(LEFT(B25,6)))*(ci_pa_clinico!$B:$B=C25), 0)), "")} -> - | K25: {=IFERROR(INDEX(aps_equipes_esf!$C:$C, MATCH(1, (VALUE(LEFT(aps_equipes_esf!$A:$A,6))=VALUE(LEFT(B25,6)))*(aps_equipes_esf!$B:$B=C25), 0)), "")} -> 56 | L25: {=IFERROR(INDEX(casos!$C:$C, MATCH(1, (VALUE(LEFT(casos!$A:$A,6))=VALUE(LEFT(B25,6)))*(casos!$B:$B=C25), 0)), "")} -> 82 | M25: {=IFERROR(INDEX(srag!$D:$D, MATCH(1, (VALUE(LEFT(srag!$A:$A,6))=VALUE(LEFT(B25,6)))*(srag!$C:$C=C25), 0)), "")} -> 11 | N25: {=IFERROR(INDEX(fesp!$E:$E, MATCH(1, (VALUE(LEFT(fesp!$A:$A,6))=VALUE(LEFT(B25,6)))*(fesp!$C:$C=C25), 0)), "")} -> 371 | O25: {=IFERROR(INDEX(fesp!$F:$F, MATCH(1, (VALUE(LEFT(fesp!$A:$A,6))=VALUE(LEFT(B25,6)))*(fesp!$C:$C=C25), 0)), "")} -> 1843 | P25: {=IFERROR(INDEX(fesp!$G:$G, MATCH(1, (VALUE(LEFT(fesp!$A:$A,6))=VALUE(LEFT(B25,6)))*(fesp!$C:$C=C25), 0)), "")} -> 2183881 | Q25: {=IFERROR(INDEX(fesp!$H:$H, MATCH(1, (VALUE(LEFT(fesp!$A:$A,6))=VALUE(LEFT(B25,6)))*(fesp!$C:$C=C25), 0)), "")} -> 86 | R25: {=IFERROR(INDEX(fesp!$I:$I, MATCH(1, (VALUE(LEFT(fesp!$A:$A,6))=VALUE(LEFT(B25,6)))*(fesp!$C:$C=C25), 0)), "")} -> 32965 | S25: {=IFERROR(INDEX(fesp!$J:$J, MATCH(1, (VALUE(LEFT(fesp!$A:$A,6))=VALUE(LEFT(B25,6)))*(fesp!$C:$C=C25), 0)), "")} -> 339347
A26: Boa Vista (RR) | B26: 1400100 | C26: 2017 | D26: {=IFERROR(INDEX(fesp!$D:$D, MATCH(1, (VALUE(LEFT(fesp!$A:$A,6))=VALUE(LEFT(B26,6)))*(fesp!$C:$C=C26), 0)), "")} -> 0 | E26: {=IFERROR(INDEX(ft_medicos_clinicos!$C:$C, MATCH(1, (VALUE(LEFT(ft_medicos_clinicos!$A:$A,6))=VALUE(LEFT(B26,6)))*(ft_medicos_clinicos!$B:$B=C26), 0)), "")} -> 256 | F26: {=IFERROR(INDEX(ft_enfermeiros!$C:$C, MATCH(1, (VALUE(LEFT(ft_enfermeiros!$A:$A,6))=VALUE(LEFT(B26,6)))*(ft_enfermeiros!$B:$B=C26), 0)), "")} -> 425 | G26: {=IFERROR(INDEX(ft_equipes_acs!$C:$C, MATCH(1, (VALUE(LEFT(ft_equipes_acs!$A:$A,6))=VALUE(LEFT(B26,6)))*(ft_equipes_acs!$B:$B=C26), 0)), "")} | H26: {=IFERROR(INDEX(ci_leitos_internacao!$C:$C, MATCH(1, (VALUE(LEFT(ci_leitos_internacao!$A:$A,6))=VALUE(LEFT(B26,6)))*(ci_leitos_internacao!$B:$B=C26), 0)), "")} -> 744 | I26: {=IFERROR(INDEX(ci_hospitais_internacao!$C:$C, MATCH(1, (VALUE(LEFT(ci_hospitais_internacao!$A:$A,6))=VALUE(LEFT(B26,6)))*(ci_hospitais_internacao!$B:$B=C26), 0)), "")} -> 2 | J26: {=IFERROR(INDEX(ci_pa_clinico!$C:$C, MATCH(1, (VALUE(LEFT(ci_pa_clinico!$A:$A,6))=VALUE(LEFT(B26,6)))*(ci_pa_clinico!$B:$B=C26), 0)), "")} -> - | K26: {=IFERROR(INDEX(aps_equipes_esf!$C:$C, MATCH(1, (VALUE(LEFT(aps_equipes_esf!$A:$A,6))=VALUE(LEFT(B26,6)))*(aps_equipes_esf!$B:$B=C26), 0)), "")} -> 50 | L26: {=IFERROR(INDEX(casos!$C:$C, MATCH(1, (VALUE(LEFT(casos!$A:$A,6))=VALUE(LEFT(B26,6)))*(casos!$B:$B=C26), 0)), "")} -> 203 | M26: {=IFERROR(INDEX(srag!$D:$D, MATCH(1, (VALUE(LEFT(srag!$A:$A,6))=VALUE(LEFT(B26,6)))*(srag!$C:$C=C26), 0)), "")} -> 0 | N26: {=IFERROR(INDEX(fesp!$E:$E, MATCH(1, (VALUE(LEFT(fesp!$A:$A,6))=VALUE(LEFT(B26,6)))*(fesp!$C:$C=C26), 0)), "")} -> 319 | O26: {=IFERROR(INDEX(fesp!$F:$F, MATCH(1, (VALUE(LEFT(fesp!$A:$A,6))=VALUE(LEFT(B26,6)))*(fesp!$C:$C=C26), 0)), "")} -> 1658 | P26: {=IFERROR(INDEX(fesp!$G:$G, MATCH(1, (VALUE(LEFT(fesp!$A:$A,6))=VALUE(LEFT(B26,6)))*(fesp!$C:$C=C26), 0)), "")} -> 2401679 | Q26: {=IFERROR(INDEX(fesp!$H:$H, MATCH(1, (VALUE(LEFT(fesp!$A:$A,6))=VALUE(LEFT(B26,6)))*(fesp!$C:$C=C26), 0)), "")} -> 163 | R26: {=IFERROR(INDEX(fesp!$I:$I, MATCH(1, (VALUE(LEFT(fesp!$A:$A,6))=VALUE(LEFT(B26,6)))*(fesp!$C:$C=C26), 0)), "")} -> 20473 | S26: {=IFERROR(INDEX(fesp!$J:$J, MATCH(1, (VALUE(LEFT(fesp!$A:$A,6))=VALUE(LEFT(B26,6)))*(fesp!$C:$C=C26), 0)), "")} -> 129127
